Workbook

Sheet Jahresübersicht
A1: Erziehungsdepartement des Kantons Schaffhausen
A2: Dienststelle Familie und Jugend
A3: Frauengasse 12/16
A4: E-mail | B4: dokumente-kjf@sh.ch
A8: Jahresübersicht 2026 | B8: Total Abrechnung | C8: BeGu Abrechnung | D8: Admin Aufwand | E8: Angewiesen am | G8: Einrichtung / Abteilung
A9: Januar | B9: =IF(Januar!C8>0,Januar!C8,0) -> 0 | C9: =IF(Januar!C6>0,Januar!C6,0) -> 0 | D9: =IF(Januar!C7>0,Januar!C7,0) -> 0 | E9: - | G9: Name
A10: Februar | B10: =IF(Februar!C8>0,Februar!C8,0) -> 0 | C10: =IF(Februar!C6>0,Februar!C6,0) -> 0 | D10: =IF(Februar!C7>0,Februar!C7,0) -> 0 | E10: - | G10: Adresse / Strasse
A11: März | B11: =IF(März!C8>0,März!C8,0) -> 0 | C11: =IF(März!C6>0,März!C6,0) -> 0 | D11: =IF(März!C7>0,März!C7,0) -> 0 | E11: - | G11: PLZ / Ort
A12: April | B12: =IF(April!C8>0,April!C8,0) -> 0 | C12: =IF(April!C6>0,April!C6,0) -> 0 | D12: =IF(April!C7>0,April!C7,0) -> 0 | E12: - | G12: Verantwortliche Person
A13: Mai | B13: =IF(Mai!C8>0,Mai!C8,0) -> 0 | C13: =IF(Mai!C6>0,Mai!C6,0) -> 0 | D13: =IF(Mai!C7>0,Mai!C7,0) -> 0 | E13: - | G13: Name / Vorname
A14: Juni | B14: =IF(Juni!C8>0,Juni!C8,0) -> 0 | C14: =IF(Juni!C6>0,Juni!C6,0) -> 0 | D14: =IF(Juni!C7>0,Juni!C7,0) -> 0 | E14: - | G14: Funktion
A15: Juli | B15: =IF(Juli!C8>0,Juli!C8,0) -> 0 | C15: =IF(Juli!C6>0,Juli!C6,0) -> 0 | D15: =IF(Juli!C7>0,Juli!C7,0) -> 0 | E15: - | G15: Telefon
A16: August | B16: =IF(August!C8>0,August!C8,0) -> 0 | C16: =IF(August!C6>0,August!C6,0) -> 0 | D16: =IF(August!C7>0,August!C7,0) -> 0 | E16: - | G16: E-Mail
A17: September | B17: =IF(September!C8>0,September!C8,0) -> 0 | C17: =IF(September!C6>0,September!C6,0) -> 0 | D17: =IF(September!C7>0,September!C7,0) -> 0 | E17: - | G17: Auszahlen an
A18: Oktober | B18: =IF(Oktober!C8>0,Oktober!C8,0) -> 0 | C18: =IF(Oktober!C6>0,Oktober!C6,0) -> 0 | D18: =IF(Oktober!C7>0,Oktober!C7,0) -> 0 | E18: - | G18: Kontoverbindung
A19: November | B19: =IF(November!C8>0,November!C8,0) -> 0 | C19: =IF(November!C6>0,November!C6,0) -> 0 | D19: =IF(November!C7>0,November!C7,0) -> 0 | E19: - | G19: Kontonummer
A20: Dezember | B20: =IF(Dezember!C8>0,Dezember!C8,0) -> 0 | C20: =IF(Dezember!C6>0,Dezember!C6,0) -> 0 | D20: =IF(Dezember!C7>0,Dezember!C7,0) -> 0 | E20: - | G20: IBAN
A23: Total Betreuungsgutschriften durch den Kanton Schaffhausen im Abrechnungsjahr 2026
A24: Total | B24: =SUM(B9:B20) -> 0 | C24: =SUM(C9:C20) -> 0 | D24: =SUM(D9:D20) -> 0
A26: Allgemeine Bemerkungen
A36: Stichkontrollen der DSFJ sind möglich und zu gewähren.
A38: Bitte gesamtes File elektronisch übermitteln an: dokumente-kjf@sh.ch
B40: Hellgrüner und / oder weiss umrahmter Bereich: Eingabebereich Betreuungseinrichtungen
B43: Gelber gesperrter Bereich: Kanton Schaffhausen
A46: Stichtage:
A47: Jan-Juli: | B47: 44043
A48: Aug-Dez: | B48: 44408

Sheet Januar
A1: Abrechnungsformular kantonale Betreuungsgutschriften (BeGu) im Vorschulbereich | H1: SHR 860.100 und SHR 860.101
A3: Abrechnung kompakt | C3: 46023
A4: BeGu Total 1/2 Tag | C4: =$G$112 -> 0
A5: BeGu Total ganzer Tag | C5: =$H$112 -> 0 | T5: Legende
A6: BeGu Total | C6: =$I$112 -> 0 | T6: x = ganzer Krippentag (resp. kostenpflichtiger Ferien- / Krankheitstag)
A7: Entschädigung | T7: hT = 1/2 Krippentag (resp. kostenpflichtiger Ferien- / Krankheitstag)
A8: Totalbetrag | C8: =C6+C7 -> 0 | T8: f = Ferien / Krankheit (kostenfrei)
A9: Angewiesen am | C9: =Jahresübersicht!E9 -> -
O10: Ausfüllen, wenn pauschal 4 Wochen (plus Zusatztage) verrechnet werden | W10: Ausfüllen, wenn tatsächliche Anzahl Tage im Monat (plus Zusatztage) verrechnet werden (Zusatztage können farbig markiert werden)
A11: Nr. | B11: Name | C11: Vorname | D11: Geburtsdatum | E11: 1/2 Tage (min. 4h) | F11: Tage (min. 8h) | G11: BeGu 1/2 Tag | H11: BeGu ganzer Tag | I11: BeGu Total | J11: Entschädi- gung | K11: Abgleich HT | L11: Abgleich GT | M11: 1/2 Tage | N11: ganze Tage | O11: Montag | P11: Dienstag | Q11: Mittwoch | R11: Donnerstag | S11: Freitag | T11: Anzahl abweichende 1/2 Tage | U11: Anzahl abweichende ganze Tage | W11: 1 | X11: 2 | Y11: 3 | Z11: 4 | AA11: 5 | AB11: 6 | AC11: 7 | AD11: 8 | AE11: 9 | AF11: 10 | AG11: 11 | AH11: 12 | AI11: 13 | AJ11: 14 | AK11: 15 | AL11: 16 | AM11: 17 | AN11: 18 | AO11: 19 | AP11: 20 | AQ11: 21 | AR11: 22 | AS11: 23 | AT11: 24 | AU11: 25 | AV11: 26 | AW11: 27 | AX11: 28 | AY11: 29 | AZ11: 30 | BA11: 31
A12: 1 | G12: =IF(ISBLANK(E12),"",E12*10) | H12: =IF(ISBLANK(F12),"",F12*20) | I12: =SUM(G12,H12) -> 0 | J12: =IF(I12>0,12,"") | K12: =IF(M12=E12,"","X") | L12: =IF(N12=F12,"","X") | M12: =(IF(O12="hT",4,0))+(IF(P12="hT",4,0))+(IF(Q12="hT",4,0))+(IF(R12="hT",4,0))+(IF(S12="hT",4,0))+T12+(COUNTIF(W12:BA12,"hT")) -> 0 | N12: =(IF(O12="x",4,0))+(IF(P12="x",4,0))+(IF(Q12="x",4,0))+(IF(R12="x",4,0))+(IF(S12="x",4,0))+U12+(COUNTIF(W12:BA12,"x")) -> 0 | V12: Entweder ↑ oder ↓ ausfüllen!
A13: 2 | G13: =IF(ISBLANK(E13),"",E13*10) | H13: =IF(ISBLANK(F13),"",F13*20) | I13: =SUM(G13,H13) -> 0 | J13: =IF(I13>0,12,"") | K13: =IF(M13=E13,"","X") | L13: =IF(N13=F13,"","X") | M13: =(IF(O13="hT",4,0))+(IF(P13="hT",4,0))+(IF(Q13="hT",4,0))+(IF(R13="hT",4,0))+(IF(S13="hT",4,0))+T13+(COUNTIF(W13:BA13,"hT")) -> 0 | N13: =(IF(O13="x",4,0))+(IF(P13="x",4,0))+(IF(Q13="x",4,0))+(IF(R13="x",4,0))+(IF(S13="x",4,0))+U13+(COUNTIF(W13:BA13,"x")) -> 0
A14: 3 | G14: =IF(ISBLANK(E14),"",E14*10) | H14: =IF(ISBLANK(F14),"",F14*20) | I14: =SUM(G14,H14) -> 0 | J14: =IF(I14>0,12,"") | K14: =IF(M14=E14,"","X") | L14: =IF(N14=F14,"","X") | M14: =(IF(O14="hT",4,0))+(IF(P14="hT",4,0))+(IF(Q14="hT",4,0))+(IF(R14="hT",4,0))+(IF(S14="hT",4,0))+T14+(COUNTIF(W14:BA14,"hT")) -> 0 | N14: =(IF(O14="x",4,0))+(IF(P14="x",4,0))+(IF(Q14="x",4,0))+(IF(R14="x",4,0))+(IF(S14="x",4,0))+U14+(COUNTIF(W14:BA14,"x")) -> 0
A15: 4 | G15: =IF(ISBLANK(E15),"",E15*10) | H15: =IF(ISBLANK(F15),"",F15*20) | I15: =SUM(G15,H15) -> 0 | J15: =IF(I15>0,12,"") | K15: =IF(M15=E15,"","X") | L15: =IF(N15=F15,"","X") | M15: =(IF(O15="hT",4,0))+(IF(P15="hT",4,0))+(IF(Q15="hT",4,0))+(IF(R15="hT",4,0))+(IF(S15="hT",4,0))+T15+(COUNTIF(W15:BA15,"hT")) -> 0 | N15: =(IF(O15="x",4,0))+(IF(P15="x",4,0))+(IF(Q15="x",4,0))+(IF(R15="x",4,0))+(IF(S15="x",4,0))+U15+(COUNTIF(W15:BA15,"x")) -> 0
A16: 5 | G16: =IF(ISBLANK(E16),"",E16*10) | H16: =IF(ISBLANK(F16),"",F16*20) | I16: =SUM(G16,H16) -> 0 | J16: =IF(I16>0,12,"") | K16: =IF(M16=E16,"","X") | L16: =IF(N16=F16,"","X") | M16: =(IF(O16="hT",4,0))+(IF(P16="hT",4,0))+(IF(Q16="hT",4,0))+(IF(R16="hT",4,0))+(IF(S16="hT",4,0))+T16+(COUNTIF(W16:BA16,"hT")) -> 0 | N16: =(IF(O16="x",4,0))+(IF(P16="x",4,0))+(IF(Q16="x",4,0))+(IF(R16="x",4,0))+(IF(S16="x",4,0))+U16+(COUNTIF(W16:BA16,"x")) -> 0
A17: 6 | G17: =IF(ISBLANK(E17),"",E17*10) | H17: =IF(ISBLANK(F17),"",F17*20) | I17: =SUM(G17,H17) -> 0 | J17: =IF(I17>0,12,"") | K17: =IF(M17=E17,"","X") | L17: =IF(N17=F17,"","X") | M17: =(IF(O17="hT",4,0))+(IF(P17="hT",4,0))+(IF(Q17="hT",4,0))+(IF(R17="hT",4,0))+(IF(S17="hT",4,0))+T17+(COUNTIF(W17:BA17,"hT")) -> 0 | N17: =(IF(O17="x",4,0))+(IF(P17="x",4,0))+(IF(Q17="x",4,0))+(IF(R17="x",4,0))+(IF(S17="x",4,0))+U17+(COUNTIF(W17:BA17,"x")) -> 0
A18: 7 | G18: =IF(ISBLANK(E18),"",E18*10) | H18: =IF(ISBLANK(F18),"",F18*20) | I18: =SUM(G18,H18) -> 0 | J18: =IF(I18>0,12,"") | K18: =IF(M18=E18,"","X") | L18: =IF(N18=F18,"","X") | M18: =(IF(O18="hT",4,0))+(IF(P18="hT",4,0))+(IF(Q18="hT",4,0))+(IF(R18="hT",4,0))+(IF(S18="hT",4,0))+T18+(COUNTIF(W18:BA18,"hT")) -> 0 | N18: =(IF(O18="x",4,0))+(IF(P18="x",4,0))+(IF(Q18="x",4,0))+(IF(R18="x",4,0))+(IF(S18="x",4,0))+U18+(COUNTIF(W18:BA18,"x")) -> 0
A19: 8 | G19: =IF(ISBLANK(E19),"",E19*10) | H19: =IF(ISBLANK(F19),"",F19*20) | I19: =SUM(G19,H19) -> 0 | J19: =IF(I19>0,12,"") | K19: =IF(M19=E19,"","X") | L19: =IF(N19=F19,"","X") | M19: =(IF(O19="hT",4,0))+(IF(P19="hT",4,0))+(IF(Q19="hT",4,0))+(IF(R19="hT",4,0))+(IF(S19="hT",4,0))+T19+(COUNTIF(W19:BA19,"hT")) -> 0 | N19: =(IF(O19="x",4,0))+(IF(P19="x",4,0))+(IF(Q19="x",4,0))+(IF(R19="x",4,0))+(IF(S19="x",4,0))+U19+(COUNTIF(W19:BA19,"x")) -> 0
A20: 9 | G20: =IF(ISBLANK(E20),"",E20*10) | H20: =IF(ISBLANK(F20),"",F20*20) | I20: =SUM(G20,H20) -> 0 | J20: =IF(I20>0,12,"") | K20: =IF(M20=E20,"","X") | L20: =IF(N20=F20,"","X") | M20: =(IF(O20="hT",4,0))+(IF(P20="hT",4,0))+(IF(Q20="hT",4,0))+(IF(R20="hT",4,0))+(IF(S20="hT",4,0))+T20+(COUNTIF(W20:BA20,"hT")) -> 0 | N20: =(IF(O20="x",4,0))+(IF(P20="x",4,0))+(IF(Q20="x",4,0))+(IF(R20="x",4,0))+(IF(S20="x",4,0))+U20+(COUNTIF(W20:BA20,"x")) -> 0
A21: 10 | G21: =IF(ISBLANK(E21),"",E21*10) | H21: =IF(ISBLANK(F21),"",F21*20) | I21: =SUM(G21,H21) -> 0 | J21: =IF(I21>0,12,"") | K21: =IF(M21=E21,"","X") | L21: =IF(N21=F21,"","X") | M21: =(IF(O21="hT",4,0))+(IF(P21="hT",4,0))+(IF(Q21="hT",4,0))+(IF(R21="hT",4,0))+(IF(S21="hT",4,0))+T21+(COUNTIF(W21:BA21,"hT")) -> 0 | N21: =(IF(O21="x",4,0))+(IF(P21="x",4,0))+(IF(Q21="x",4,0))+(IF(R21="x",4,0))+(IF(S21="x",4,0))+U21+(COUNTIF(W21:BA21,"x")) -> 0
A22: 11 | G22: =IF(ISBLANK(E22),"",E22*10) | H22: =IF(ISBLANK(F22),"",F22*20) | I22: =SUM(G22,H22) -> 0 | J22: =IF(I22>0,12,"") | K22: =IF(M22=E22,"","X") | L22: =IF(N22=F22,"","X") | M22: =(IF(O22="hT",4,0))+(IF(P22="hT",4,0))+(IF(Q22="hT",4,0))+(IF(R22="hT",4,0))+(IF(S22="hT",4,0))+T22+(COUNTIF(W22:BA22,"hT")) -> 0 | N22: =(IF(O22="x",4,0))+(IF(P22="x",4,0))+(IF(Q22="x",4,0))+(IF(R22="x",4,0))+(IF(S22="x",4,0))+U22+(COUNTIF(W22:BA22,"x")) -> 0
A23: 12 | G23: =IF(ISBLANK(E23),"",E23*10) | H23: =IF(ISBLANK(F23),"",F23*20) | I23: =SUM(G23,H23) -> 0 | J23: =IF(I23>0,12,"") | K23: =IF(M23=E23,"","X") | L23: =IF(N23=F23,"","X") | M23: =(IF(O23="hT",4,0))+(IF(P23="hT",4,0))+(IF(Q23="hT",4,0))+(IF(R23="hT",4,0))+(IF(S23="hT",4,0))+T23+(COUNTIF(W23:BA23,"hT")) -> 0 | N23: =(IF(O23="x",4,0))+(IF(P23="x",4,0))+(IF(Q23="x",4,0))+(IF(R23="x",4,0))+(IF(S23="x",4,0))+U23+(COUNTIF(W23:BA23,"x")) -> 0
A24: 13 | G24: =IF(ISBLANK(E24),"",E24*10) | H24: =IF(ISBLANK(F24),"",F24*20) | I24: =SUM(G24,H24) -> 0 | J24: =IF(I24>0,12,"") | K24: =IF(M24=E24,"","X") | L24: =IF(N24=F24,"","X") | M24: =(IF(O24="hT",4,0))+(IF(P24="hT",4,0))+(IF(Q24="hT",4,0))+(IF(R24="hT",4,0))+(IF(S24="hT",4,0))+T24+(COUNTIF(W24:BA24,"hT")) -> 0 | N24: =(IF(O24="x",4,0))+(IF(P24="x",4,0))+(IF(Q24="x",4,0))+(IF(R24="x",4,0))+(IF(S24="x",4,0))+U24+(COUNTIF(W24:BA24,"x")) -> 0
... A111: 100 | G111: =IF(ISBLANK(E111),"",E111*10) | H111: =IF(ISBLANK(F111),"",F111*20) | I111: =SUM(G111,H111) -> 0 | J111: =IF(I111>0,12,"") | K111: =IF(M111=E111,"","X") | L111: =IF(N111=F111,"","X") | M111: =(IF(O111="hT",4,0))+(IF(P111="hT",4,0))+(IF(Q111="hT",4,0))+(IF(R111="hT",4,0))+(IF(S111="hT",4,0))+T111+(COUNTIF(W111:BA111,"hT")) -> 0 | N111: =(IF(O111="x",4,0))+(IF(P111="x",4,0))+(IF(Q111="x",4,0))+(IF(R111="x",4,0))+(IF(S111="x",4,0))+U111+(COUNTIF(W111:BA111,"x")) -> 0
B112: Anzahl Kinder | C112: =COUNTA(C12:C111) -> 0 | D112: Total | E112: =SUM(E12:E111) -> 0 | F112: =SUM(F12:F111) -> 0 | G112: =SUM(G12:G111) -> 0 | H112: =SUM(H12:H111) -> 0 | I112: =SUM(I12:I111) -> 0 | J112: =IF(SUM(J12:J111)=0,0,IF(SUM(J12:J111)<20,20,SUM(J12:J111))) -> 0
A115: Nr. | B115: Bemerkung

Sheet Februar
A1: Abrechnungsformular kantonale Betreuungsgutschriften (BeGu) im Vorschulbereich | H1: SHR 860.100 und SHR 860.101
A3: Abrechnung kompakt | C3: 46054
A4: BeGu Total 1/2 Tag | C4: =$G$112 -> 0
A5: BeGu Total ganzer Tag | C5: =$H$112 -> 0 | T5: Legende
A6: BeGu Total | C6: =$I$112 -> 0 | T6: x = ganzer Krippentag (resp. kostenpflichtiger Ferien- / Krankheitstag)
A7: Entschädigung | T7: hT = 1/2 Krippentag (resp. kostenpflichtiger Ferien- / Krankheitstag)
A8: Totalbetrag | C8: =C6+C7 -> 0 | T8: f = Ferien / Krankheit (kostenfrei)
A9: Angewiesen am | C9: =Jahresübersicht!E10 -> -
O10: Ausfüllen, wenn pauschal 4 Wochen (plus Zusatztage) verrechnet werden | W10: Ausfüllen, wenn tatsächliche Anzahl Tage im Monat (plus Zusatztage) verrechnet werden (Zusatztage können farbig markiert werden)
A11: Nr. | B11: Name | C11: Vorname | D11: Geburtsdatum | E11: 1/2 Tage (min. 4h) | F11: Tage (min. 8h) | G11: BeGu 1/2 Tag | H11: BeGu ganzer Tag | I11: BeGu Total | J11: Entschädi- gung | K11: Abgleich HT | L11: Abgleich GT | M11: 1/2 Tage | N11: ganze Tage | O11: Montag | P11: Dienstag | Q11: Mittwoch | R11: Donnerstag | S11: Freitag | T11: Anzahl abweichende 1/2 Tage | U11: Anzahl abweichende ganze Tage | W11: 1 | X11: 2 | Y11: 3 | Z11: 4 | AA11: 5 | AB11: 6 | AC11: 7 | AD11: 8 | AE11: 9 | AF11: 10 | AG11: 11 | AH11: 12 | AI11: 13 | AJ11: 14 | AK11: 15 | AL11: 16 | AM11: 17 | AN11: 18 | AO11: 19 | AP11: 20 | AQ11: 21 | AR11: 22 | AS11: 23 | AT11: 24 | AU11: 25 | AV11: 26 | AW11: 27 | AX11: 28
A12: 1 | G12: =IF(ISBLANK(E12),"",E12*10) | H12: =IF(ISBLANK(F12),"",F12*20) | I12: =SUM(G12,H12) -> 0 | J12: =IF(I12>0,12,"") | K12: =IF(M12=E12,"","X") | L12: =IF(N12=F12,"","X") | M12: =(IF(O12="hT",4,0))+(IF(P12="hT",4,0))+(IF(Q12="hT",4,0))+(IF(R12="hT",4,0))+(IF(S12="hT",4,0))+T12+(COUNTIF(W12:AX12,"hT")) -> 0 | N12: =(IF(O12="x",4,0))+(IF(P12="x",4,0))+(IF(Q12="x",4,0))+(IF(R12="x",4,0))+(IF(S12="x",4,0))+U12+(COUNTIF(W12:AX12,"x")) -> 0 | V12: Entweder ↑ oder ↓ ausfüllen!
A13: 2 | G13: =IF(ISBLANK(E13),"",E13*10) | H13: =IF(ISBLANK(F13),"",F13*20) | I13: =SUM(G13,H13) -> 0 | J13: =IF(I13>0,12,"") | K13: =IF(M13=E13,"","X") | L13: =IF(N13=F13,"","X") | M13: =(IF(O13="hT",4,0))+(IF(P13="hT",4,0))+(IF(Q13="hT",4,0))+(IF(R13="hT",4,0))+(IF(S13="hT",4,0))+T13+(COUNTIF(W13:AX13,"hT")) -> 0 | N13: =(IF(O13="x",4,0))+(IF(P13="x",4,0))+(IF(Q13="x",4,0))+(IF(R13="x",4,0))+(IF(S13="x",4,0))+U13+(COUNTIF(W13:AX13,"x")) -> 0
A14: 3 | G14: =IF(ISBLANK(E14),"",E14*10) | H14: =IF(ISBLANK(F14),"",F14*20) | I14: =SUM(G14,H14) -> 0 | J14: =IF(I14>0,12,"") | K14: =IF(M14=E14,"","X") | L14: =IF(N14=F14,"","X") | M14: =(IF(O14="hT",4,0))+(IF(P14="hT",4,0))+(IF(Q14="hT",4,0))+(IF(R14="hT",4,0))+(IF(S14="hT",4,0))+T14+(COUNTIF(W14:AX14,"hT")) -> 0 | N14: =(IF(O14="x",4,0))+(IF(P14="x",4,0))+(IF(Q14="x",4,0))+(IF(R14="x",4,0))+(IF(S14="x",4,0))+U14+(COUNTIF(W14:AX14,"x")) -> 0
A15: 4 | G15: =IF(ISBLANK(E15),"",E15*10) | H15: =IF(ISBLANK(F15),"",F15*20) | I15: =SUM(G15,H15) -> 0 | J15: =IF(I15>0,12,"") | K15: =IF(M15=E15,"","X") | L15: =IF(N15=F15,"","X") | M15: =(IF(O15="hT",4,0))+(IF(P15="hT",4,0))+(IF(Q15="hT",4,0))+(IF(R15="hT",4,0))+(IF(S15="hT",4,0))+T15+(COUNTIF(W15:AX15,"hT")) -> 0 | N15: =(IF(O15="x",4,0))+(IF(P15="x",4,0))+(IF(Q15="x",4,0))+(IF(R15="x",4,0))+(IF(S15="x",4,0))+U15+(COUNTIF(W15:AX15,"x")) -> 0
A16: 5 | G16: =IF(ISBLANK(E16),"",E16*10) | H16: =IF(ISBLANK(F16),"",F16*20) | I16: =SUM(G16,H16) -> 0 | J16: =IF(I16>0,12,"") | K16: =IF(M16=E16,"","X") | L16: =IF(N16=F16,"","X") | M16: =(IF(O16="hT",4,0))+(IF(P16="hT",4,0))+(IF(Q16="hT",4,0))+(IF(R16="hT",4,0))+(IF(S16="hT",4,0))+T16+(COUNTIF(W16:AX16,"hT")) -> 0 | N16: =(IF(O16="x",4,0))+(IF(P16="x",4,0))+(IF(Q16="x",4,0))+(IF(R16="x",4,0))+(IF(S16="x",4,0))+U16+(COUNTIF(W16:AX16,"x")) -> 0
A17: 6 | G17: =IF(ISBLANK(E17),"",E17*10) | H17: =IF(ISBLANK(F17),"",F17*20) | I17: =SUM(G17,H17) -> 0 | J17: =IF(I17>0,12,"") | K17: =IF(M17=E17,"","X") | L17: =IF(N17=F17,"","X") | M17: =(IF(O17="hT",4,0))+(IF(P17="hT",4,0))+(IF(Q17="hT",4,0))+(IF(R17="hT",4,0))+(IF(S17="hT",4,0))+T17+(COUNTIF(W17:AX17,"hT")) -> 0 | N17: =(IF(O17="x",4,0))+(IF(P17="x",4,0))+(IF(Q17="x",4,0))+(IF(R17="x",4,0))+(IF(S17="x",4,0))+U17+(COUNTIF(W17:AX17,"x")) -> 0
A18: 7 | G18: =IF(ISBLANK(E18),"",E18*10) | H18: =IF(ISBLANK(F18),"",F18*20) | I18: =SUM(G18,H18) -> 0 | J18: =IF(I18>0,12,"") | K18: =IF(M18=E18,"","X") | L18: =IF(N18=F18,"","X") | M18: =(IF(O18="hT",4,0))+(IF(P18="hT",4,0))+(IF(Q18="hT",4,0))+(IF(R18="hT",4,0))+(IF(S18="hT",4,0))+T18+(COUNTIF(W18:AX18,"hT")) -> 0 | N18: =(IF(O18="x",4,0))+(IF(P18="x",4,0))+(IF(Q18="x",4,0))+(IF(R18="x",4,0))+(IF(S18="x",4,0))+U18+(COUNTIF(W18:AX18,"x")) -> 0
A19: 8 | G19: =IF(ISBLANK(E19),"",E19*10) | H19: =IF(ISBLANK(F19),"",F19*20) | I19: =SUM(G19,H19) -> 0 | J19: =IF(I19>0,12,"") | K19: =IF(M19=E19,"","X") | L19: =IF(N19=F19,"","X") | M19: =(IF(O19="hT",4,0))+(IF(P19="hT",4,0))+(IF(Q19="hT",4,0))+(IF(R19="hT",4,0))+(IF(S19="hT",4,0))+T19+(COUNTIF(W19:AX19,"hT")) -> 0 | N19: =(IF(O19="x",4,0))+(IF(P19="x",4,0))+(IF(Q19="x",4,0))+(IF(R19="x",4,0))+(IF(S19="x",4,0))+U19+(COUNTIF(W19:AX19,"x")) -> 0
A20: 9 | G20: =IF(ISBLANK(E20),"",E20*10) | H20: =IF(ISBLANK(F20),"",F20*20) | I20: =SUM(G20,H20) -> 0 | J20: =IF(I20>0,12,"") | K20: =IF(M20=E20,"","X") | L20: =IF(N20=F20,"","X") | M20: =(IF(O20="hT",4,0))+(IF(P20="hT",4,0))+(IF(Q20="hT",4,0))+(IF(R20="hT",4,0))+(IF(S20="hT",4,0))+T20+(COUNTIF(W20:AX20,"hT")) -> 0 | N20: =(IF(O20="x",4,0))+(IF(P20="x",4,0))+(IF(Q20="x",4,0))+(IF(R20="x",4,0))+(IF(S20="x",4,0))+U20+(COUNTIF(W20:AX20,"x")) -> 0
A21: 10 | G21: =IF(ISBLANK(E21),"",E21*10) | H21: =IF(ISBLANK(F21),"",F21*20) | I21: =SUM(G21,H21) -> 0 | J21: =IF(I21>0,12,"") | K21: =IF(M21=E21,"","X") | L21: =IF(N21=F21,"","X") | M21: =(IF(O21="hT",4,0))+(IF(P21="hT",4,0))+(IF(Q21="hT",4,0))+(IF(R21="hT",4,0))+(IF(S21="hT",4,0))+T21+(COUNTIF(W21:AX21,"hT")) -> 0 | N21: =(IF(O21="x",4,0))+(IF(P21="x",4,0))+(IF(Q21="x",4,0))+(IF(R21="x",4,0))+(IF(S21="x",4,0))+U21+(COUNTIF(W21:AX21,"x")) -> 0
A22: 11 | G22: =IF(ISBLANK(E22),"",E22*10) | H22: =IF(ISBLANK(F22),"",F22*20) | I22: =SUM(G22,H22) -> 0 | J22: =IF(I22>0,12,"") | K22: =IF(M22=E22,"","X") | L22: =IF(N22=F22,"","X") | M22: =(IF(O22="hT",4,0))+(IF(P22="hT",4,0))+(IF(Q22="hT",4,0))+(IF(R22="hT",4,0))+(IF(S22="hT",4,0))+T22+(COUNTIF(W22:AX22,"hT")) -> 0 | N22: =(IF(O22="x",4,0))+(IF(P22="x",4,0))+(IF(Q22="x",4,0))+(IF(R22="x",4,0))+(IF(S22="x",4,0))+U22+(COUNTIF(W22:AX22,"x")) -> 0
A23: 12 | G23: =IF(ISBLANK(E23),"",E23*10) | H23: =IF(ISBLANK(F23),"",F23*20) | I23: =SUM(G23,H23) -> 0 | J23: =IF(I23>0,12,"") | K23: =IF(M23=E23,"","X") | L23: =IF(N23=F23,"","X") | M23: =(IF(O23="hT",4,0))+(IF(P23="hT",4,0))+(IF(Q23="hT",4,0))+(IF(R23="hT",4,0))+(IF(S23="hT",4,0))+T23+(COUNTIF(W23:AX23,"hT")) -> 0 | N23: =(IF(O23="x",4,0))+(IF(P23="x",4,0))+(IF(Q23="x",4,0))+(IF(R23="x",4,0))+(IF(S23="x",4,0))+U23+(COUNTIF(W23:AX23,"x")) -> 0
A24: 13 | G24: =IF(ISBLANK(E24),"",E24*10) | H24: =IF(ISBLANK(F24),"",F24*20) | I24: =SUM(G24,H24) -> 0 | J24: =IF(I24>0,12,"") | K24: =IF(M24=E24,"","X") | L24: =IF(N24=F24,"","X") | M24: =(IF(O24="hT",4,0))+(IF(P24="hT",4,0))+(IF(Q24="hT",4,0))+(IF(R24="hT",4,0))+(IF(S24="hT",4,0))+T24+(COUNTIF(W24:AX24,"hT")) -> 0 | N24: =(IF(O24="x",4,0))+(IF(P24="x",4,0))+(IF(Q24="x",4,0))+(IF(R24="x",4,0))+(IF(S24="x",4,0))+U24+(COUNTIF(W24:AX24,"x")) -> 0
... A111: 100 | G111: =IF(ISBLANK(E111),"",E111*10) | H111: =IF(ISBLANK(F111),"",F111*20) | I111: =SUM(G111,H111) -> 0 | J111: =IF(I111>0,12,"") | K111: =IF(M111=E111,"","X") | L111: =IF(N111=F111,"","X") | M111: =(IF(O111="hT",4,0))+(IF(P111="hT",4,0))+(IF(Q111="hT",4,0))+(IF(R111="hT",4,0))+(IF(S111="hT",4,0))+T111+(COUNTIF(W111:AX111,"hT")) -> 0 | N111: =(IF(O111="x",4,0))+(IF(P111="x",4,0))+(IF(Q111="x",4,0))+(IF(R111="x",4,0))+(IF(S111="x",4,0))+U111+(COUNTIF(W111:AX111,"x")) -> 0
B112: Anzahl Kinder | C112: =COUNTA(C12:C111) -> 0 | D112: Total | E112: =SUM(E12:E111) -> 0 | F112: =SUM(F12:F111) -> 0 | G112: =SUM(G12:G111) -> 0 | H112: =SUM(H12:H111) -> 0 | I112: =SUM(I12:I111) -> 0 | J112: =IF(SUM(J12:J111)=0,0,IF(SUM(J12:J111)<20,20,SUM(J12:J111))) -> 0
A115: Nr. | B115: Bemerkung

Sheet März
A1: Abrechnungsformular kantonale Betreuungsgutschriften (BeGu) im Vorschulbereich | H1: SHR 860.100 und SHR 860.101
A3: Abrechnung kompakt | C3: 46082
A4: BeGu Total 1/2 Tag | C4: =$G$112 -> 0
A5: BeGu Total ganzer Tag | C5: =$H$112 -> 0 | T5: Legende
A6: BeGu Total | C6: =$I$112 -> 0 | T6: x = ganzer Krippentag (resp. kostenpflichtiger Ferien- / Krankheitstag)
A7: Entschädigung | T7: hT = 1/2 Krippentag (resp. kostenpflichtiger Ferien- / Krankheitstag)
A8: Totalbetrag | C8: =C6+C7 -> 0 | T8: f = Ferien / Krankheit (kostenfrei)
A9: Angewiesen am | C9: =Jahresübersicht!E11 -> -
O10: Ausfüllen, wenn pauschal 4 Wochen (plus Zusatztage) verrechnet werden | W10: Ausfüllen, wenn tatsächliche Anzahl Tage im Monat (plus Zusatztage) verrechnet werden (Zusatztage können farbig markiert werden)
A11: Nr. | B11: Name | C11: Vorname | D11: Geburtsdatum | E11: 1/2 Tage (min. 4h) | F11: Tage (min. 8h) | G11: BeGu 1/2 Tag | H11: BeGu ganzer Tag | I11: BeGu Total | J11: Entschädi- gung | K11: Abgleich HT | L11: Abgleich GT | M11: 1/2 Tage | N11: ganze Tage | O11: Montag | P11: Dienstag | Q11: Mittwoch | R11: Donnerstag | S11: Freitag | T11: Anzahl abweichende 1/2 Tage | U11: Anzahl abweichende ganze Tage | W11: 1 | X11: 2 | Y11: 3 | Z11: 4 | AA11: 5 | AB11: 6 | AC11: 7 | AD11: 8 | AE11: 9 | AF11: 10 | AG11: 11 | AH11: 12 | AI11: 13 | AJ11: 14 | AK11: 15 | AL11: 16 | AM11: 17 | AN11: 18 | AO11: 19 | AP11: 20 | AQ11: 21 | AR11: 22 | AS11: 23 | AT11: 24 | AU11: 25 | AV11: 26 | AW11: 27 | AX11: 28 | AY11: 29 | AZ11: 30 | BA11: 31
A12: 1 | G12: =IF(ISBLANK(E12),"",E12*10) | H12: =IF(ISBLANK(F12),"",F12*20) | I12: =SUM(G12,H12) -> 0 | J12: =IF(I12>0,12,"") | K12: =IF(M12=E12,"","X") | L12: =IF(N12=F12,"","X") | M12: =(IF(O12="hT",4,0))+(IF(P12="hT",4,0))+(IF(Q12="hT",4,0))+(IF(R12="hT",4,0))+(IF(S12="hT",4,0))+T12+(COUNTIF(W12:BA12,"hT")) -> 0 | N12: =(IF(O12="x",4,0))+(IF(P12="x",4,0))+(IF(Q12="x",4,0))+(IF(R12="x",4,0))+(IF(S12="x",4,0))+U12+(COUNTIF(W12:BA12,"x")) -> 0 | V12: Entweder ↑ oder ↓ ausfüllen!
A13: 2 | G13: =IF(ISBLANK(E13),"",E13*10) | H13: =IF(ISBLANK(F13),"",F13*20) | I13: =SUM(G13,H13) -> 0 | J13: =IF(I13>0,12,"") | K13: =IF(M13=E13,"","X") | L13: =IF(N13=F13,"","X") | M13: =(IF(O13="hT",4,0))+(IF(P13="hT",4,0))+(IF(Q13="hT",4,0))+(IF(R13="hT",4,0))+(IF(S13="hT",4,0))+T13+(COUNTIF(W13:BA13,"hT")) -> 0 | N13: =(IF(O13="x",4,0))+(IF(P13="x",4,0))+(IF(Q13="x",4,0))+(IF(R13="x",4,0))+(IF(S13="x",4,0))+U13+(COUNTIF(W13:BA13,"x")) -> 0
A14: 3 | G14: =IF(ISBLANK(E14),"",E14*10) | H14: =IF(ISBLANK(F14),"",F14*20) | I14: =SUM(G14,H14) -> 0 | J14: =IF(I14>0,12,"") | K14: =IF(M14=E14,"","X") | L14: =IF(N14=F14,"","X") | M14: =(IF(O14="hT",4,0))+(IF(P14="hT",4,0))+(IF(Q14="hT",4,0))+(IF(R14="hT",4,0))+(IF(S14="hT",4,0))+T14+(COUNTIF(W14:BA14,"hT")) -> 0 | N14: =(IF(O14="x",4,0))+(IF(P14="x",4,0))+(IF(Q14="x",4,0))+(IF(R14="x",4,0))+(IF(S14="x",4,0))+U14+(COUNTIF(W14:BA14,"x")) -> 0
A15: 4 | G15: =IF(ISBLANK(E15),"",E15*10) | H15: =IF(ISBLANK(F15),"",F15*20) | I15: =SUM(G15,H15) -> 0 | J15: =IF(I15>0,12,"") | K15: =IF(M15=E15,"","X") | L15: =IF(N15=F15,"","X") | M15: =(IF(O15="hT",4,0))+(IF(P15="hT",4,0))+(IF(Q15="hT",4,0))+(IF(R15="hT",4,0))+(IF(S15="hT",4,0))+T15+(COUNTIF(W15:BA15,"hT")) -> 0 | N15: =(IF(O15="x",4,0))+(IF(P15="x",4,0))+(IF(Q15="x",4,0))+(IF(R15="x",4,0))+(IF(S15="x",4,0))+U15+(COUNTIF(W15:BA15,"x")) -> 0
A16: 5 | G16: =IF(ISBLANK(E16),"",E16*10) | H16: =IF(ISBLANK(F16),"",F16*20) | I16: =SUM(G16,H16) -> 0 | J16: =IF(I16>0,12,"") | K16: =IF(M16=E16,"","X") | L16: =IF(N16=F16,"","X") | M16: =(IF(O16="hT",4,0))+(IF(P16="hT",4,0))+(IF(Q16="hT",4,0))+(IF(R16="hT",4,0))+(IF(S16="hT",4,0))+T16+(COUNTIF(W16:BA16,"hT")) -> 0 | N16: =(IF(O16="x",4,0))+(IF(P16="x",4,0))+(IF(Q16="x",4,0))+(IF(R16="x",4,0))+(IF(S16="x",4,0))+U16+(COUNTIF(W16:BA16,"x")) -> 0
A17: 6 | G17: =IF(ISBLANK(E17),"",E17*10) | H17: =IF(ISBLANK(F17),"",F17*20) | I17: =SUM(G17,H17) -> 0 | J17: =IF(I17>0,12,"") | K17: =IF(M17=E17,"","X") | L17: =IF(N17=F17,"","X") | M17: =(IF(O17="hT",4,0))+(IF(P17="hT",4,0))+(IF(Q17="hT",4,0))+(IF(R17="hT",4,0))+(IF(S17="hT",4,0))+T17+(COUNTIF(W17:BA17,"hT")) -> 0 | N17: =(IF(O17="x",4,0))+(IF(P17="x",4,0))+(IF(Q17="x",4,0))+(IF(R17="x",4,0))+(IF(S17="x",4,0))+U17+(COUNTIF(W17:BA17,"x")) -> 0
A18: 7 | G18: =IF(ISBLANK(E18),"",E18*10) | H18: =IF(ISBLANK(F18),"",F18*20) | I18: =SUM(G18,H18) -> 0 | J18: =IF(I18>0,12,"") | K18: =IF(M18=E18,"","X") | L18: =IF(N18=F18,"","X") | M18: =(IF(O18="hT",4,0))+(IF(P18="hT",4,0))+(IF(Q18="hT",4,0))+(IF(R18="hT",4,0))+(IF(S18="hT",4,0))+T18+(COUNTIF(W18:BA18,"hT")) -> 0 | N18: =(IF(O18="x",4,0))+(IF(P18="x",4,0))+(IF(Q18="x",4,0))+(IF(R18="x",4,0))+(IF(S18="x",4,0))+U18+(COUNTIF(W18:BA18,"x")) -> 0
A19: 8 | G19: =IF(ISBLANK(E19),"",E19*10) | H19: =IF(ISBLANK(F19),"",F19*20) | I19: =SUM(G19,H19) -> 0 | J19: =IF(I19>0,12,"") | K19: =IF(M19=E19,"","X") | L19: =IF(N19=F19,"","X") | M19: =(IF(O19="hT",4,0))+(IF(P19="hT",4,0))+(IF(Q19="hT",4,0))+(IF(R19="hT",4,0))+(IF(S19="hT",4,0))+T19+(COUNTIF(W19:BA19,"hT")) -> 0 | N19: =(IF(O19="x",4,0))+(IF(P19="x",4,0))+(IF(Q19="x",4,0))+(IF(R19="x",4,0))+(IF(S19="x",4,0))+U19+(COUNTIF(W19:BA19,"x")) -> 0
A20: 9 | G20: =IF(ISBLANK(E20),"",E20*10) | H20: =IF(ISBLANK(F20),"",F20*20) | I20: =SUM(G20,H20) -> 0 | J20: =IF(I20>0,12,"") | K20: =IF(M20=E20,"","X") | L20: =IF(N20=F20,"","X") | M20: =(IF(O20="hT",4,0))+(IF(P20="hT",4,0))+(IF(Q20="hT",4,0))+(IF(R20="hT",4,0))+(IF(S20="hT",4,0))+T20+(COUNTIF(W20:BA20,"hT")) -> 0 | N20: =(IF(O20="x",4,0))+(IF(P20="x",4,0))+(IF(Q20="x",4,0))+(IF(R20="x",4,0))+(IF(S20="x",4,0))+U20+(COUNTIF(W20:BA20,"x")) -> 0
A21: 10 | G21: =IF(ISBLANK(E21),"",E21*10) | H21: =IF(ISBLANK(F21),"",F21*20) | I21: =SUM(G21,H21) -> 0 | J21: =IF(I21>0,12,"") | K21: =IF(M21=E21,"","X") | L21: =IF(N21=F21,"","X") | M21: =(IF(O21="hT",4,0))+(IF(P21="hT",4,0))+(IF(Q21="hT",4,0))+(IF(R21="hT",4,0))+(IF(S21="hT",4,0))+T21+(COUNTIF(W21:BA21,"hT")) -> 0 | N21: =(IF(O21="x",4,0))+(IF(P21="x",4,0))+(IF(Q21="x",4,0))+(IF(R21="x",4,0))+(IF(S21="x",4,0))+U21+(COUNTIF(W21:BA21,"x")) -> 0
A22: 11 | G22: =IF(ISBLANK(E22),"",E22*10) | H22: =IF(ISBLANK(F22),"",F22*20) | I22: =SUM(G22,H22) -> 0 | J22: =IF(I22>0,12,"") | K22: =IF(M22=E22,"","X") | L22: =IF(N22=F22,"","X") | M22: =(IF(O22="hT",4,0))+(IF(P22="hT",4,0))+(IF(Q22="hT",4,0))+(IF(R22="hT",4,0))+(IF(S22="hT",4,0))+T22+(COUNTIF(W22:BA22,"hT")) -> 0 | N22: =(IF(O22="x",4,0))+(IF(P22="x",4,0))+(IF(Q22="x",4,0))+(IF(R22="x",4,0))+(IF(S22="x",4,0))+U22+(COUNTIF(W22:BA22,"x")) -> 0
A23: 12 | G23: =IF(ISBLANK(E23),"",E23*10) | H23: =IF(ISBLANK(F23),"",F23*20) | I23: =SUM(G23,H23) -> 0 | J23: =IF(I23>0,12,"") | K23: =IF(M23=E23,"","X") | L23: =IF(N23=F23,"","X") | M23: =(IF(O23="hT",4,0))+(IF(P23="hT",4,0))+(IF(Q23="hT",4,0))+(IF(R23="hT",4,0))+(IF(S23="hT",4,0))+T23+(COUNTIF(W23:BA23,"hT")) -> 0 | N23: =(IF(O23="x",4,0))+(IF(P23="x",4,0))+(IF(Q23="x",4,0))+(IF(R23="x",4,0))+(IF(S23="x",4,0))+U23+(COUNTIF(W23:BA23,"x")) -> 0
A24: 13 | G24: =IF(ISBLANK(E24),"",E24*10) | H24: =IF(ISBLANK(F24),"",F24*20) | I24: =SUM(G24,H24) -> 0 | J24: =IF(I24>0,12,"") | K24: =IF(M24=E24,"","X") | L24: =IF(N24=F24,"","X") | M24: =(IF(O24="hT",4,0))+(IF(P24="hT",4,0))+(IF(Q24="hT",4,0))+(IF(R24="hT",4,0))+(IF(S24="hT",4,0))+T24+(COUNTIF(W24:BA24,"hT")) -> 0 | N24: =(IF(O24="x",4,0))+(IF(P24="x",4,0))+(IF(Q24="x",4,0))+(IF(R24="x",4,0))+(IF(S24="x",4,0))+U24+(COUNTIF(W24:BA24,"x")) -> 0
... A111: 100 | G111: =IF(ISBLANK(E111),"",E111*10) | H111: =IF(ISBLANK(F111),"",F111*20) | I111: =SUM(G111,H111) -> 0 | J111: =IF(I111>0,12,"") | K111: =IF(M111=E111,"","X") | L111: =IF(N111=F111,"","X") | M111: =(IF(O111="hT",4,0))+(IF(P111="hT",4,0))+(IF(Q111="hT",4,0))+(IF(R111="hT",4,0))+(IF(S111="hT",4,0))+T111+(COUNTIF(W111:BA111,"hT")) -> 0 | N111: =(IF(O111="x",4,0))+(IF(P111="x",4,0))+(IF(Q111="x",4,0))+(IF(R111="x",4,0))+(IF(S111="x",4,0))+U111+(COUNTIF(W111:BA111,"x")) -> 0
B112: Anzahl Kinder | C112: =COUNTA(C12:C111) -> 0 | D112: Total | E112: =SUM(E12:E111) -> 0 | F112: =SUM(F12:F111) -> 0 | G112: =SUM(G12:G111) -> 0 | H112: =SUM(H12:H111) -> 0 | I112: =SUM(I12:I111) -> 0 | J112: =IF(SUM(J12:J111)=0,0,IF(SUM(J12:J111)<20,20,SUM(J12:J111))) -> 0
A115: Nr. | B115: Bemerkung

Sheet April
A1: Abrechnungsformular kantonale Betreuungsgutschriften (BeGu) im Vorschulbereich | H1: SHR 860.100 und SHR 860.101
A3: Abrechnung kompakt | C3: 46113
A4: BeGu Total 1/2 Tag | C4: =$G$112 -> 0
A5: BeGu Total ganzer Tag | C5: =$H$112 -> 0 | T5: Legende
A6: BeGu Total | C6: =$I$112 -> 0 | T6: x = ganzer Krippentag (resp. kostenpflichtiger Ferien- / Krankheitstag)
A7: Entschädigung | T7: hT = 1/2 Krippentag (resp. kostenpflichtiger Ferien- / Krankheitstag)
A8: Totalbetrag | C8: =C6+C7 -> 0 | T8: f = Ferien / Krankheit (kostenfrei)
A9: Angewiesen am | C9: =Jahresübersicht!E12 -> -
O10: Ausfüllen, wenn pauschal 4 Wochen (plus Zusatztage) verrechnet werden | W10: Ausfüllen, wenn tatsächliche Anzahl Tage im Monat (plus Zusatztage) verrechnet werden (Zusatztage können farbig markiert werden)
A11: Nr. | B11: Name | C11: Vorname | D11: Geburtsdatum | E11: 1/2 Tage (min. 4h) | F11: Tage (min. 8h) | G11: BeGu 1/2 Tag | H11: BeGu ganzer Tag | I11: BeGu Total | J11: Entschädi- gung | K11: Abgleich HT | L11: Abgleich GT | M11: 1/2 Tage | N11: ganze Tage | O11: Montag | P11: Dienstag | Q11: Mittwoch | R11: Donnerstag | S11: Freitag | T11: Anzahl abweichende 1/2 Tage | U11: Anzahl abweichende ganze Tage | W11: 1 | X11: 2 | Y11: 3 | Z11: 4 | AA11: 5 | AB11: 6 | AC11: 7 | AD11: 8 | AE11: 9 | AF11: 10 | AG11: 11 | AH11: 12 | AI11: 13 | AJ11: 14 | AK11: 15 | AL11: 16 | AM11: 17 | AN11: 18 | AO11: 19 | AP11: 20 | AQ11: 21 | AR11: 22 | AS11: 23 | AT11: 24 | AU11: 25 | AV11: 26 | AW11: 27 | AX11: 28 | AY11: 29 | AZ11: 30
A12: 1 | G12: =IF(ISBLANK(E12),"",E12*10) | H12: =IF(ISBLANK(F12),"",F12*20) | I12: =SUM(G12,H12) -> 0 | J12: =IF(I12>0,12,"") | K12: =IF(M12=E12,"","X") | L12: =IF(N12=F12,"","X") | M12: =(IF(O12="hT",4,0))+(IF(P12="hT",4,0))+(IF(Q12="hT",4,0))+(IF(R12="hT",4,0))+(IF(S12="hT",4,0))+T12+(COUNTIF(W12:AZ12,"hT")) -> 0 | N12: =(IF(O12="x",4,0))+(IF(P12="x",4,0))+(IF(Q12="x",4,0))+(IF(R12="x",4,0))+(IF(S12="x",4,0))+U12+(COUNTIF(W12:AZ12,"x")) -> 0 | V12: Entweder ↑ oder ↓ ausfüllen!
A13: 2 | G13: =IF(ISBLANK(E13),"",E13*10) | H13: =IF(ISBLANK(F13),"",F13*20) | I13: =SUM(G13,H13) -> 0 | J13: =IF(I13>0,12,"") | K13: =IF(M13=E13,"","X") | L13: =IF(N13=F13,"","X") | M13: =(IF(O13="hT",4,0))+(IF(P13="hT",4,0))+(IF(Q13="hT",4,0))+(IF(R13="hT",4,0))+(IF(S13="hT",4,0))+T13+(COUNTIF(W13:AZ13,"hT")) -> 0 | N13: =(IF(O13="x",4,0))+(IF(P13="x",4,0))+(IF(Q13="x",4,0))+(IF(R13="x",4,0))+(IF(S13="x",4,0))+U13+(COUNTIF(W13:AZ13,"x")) -> 0
A14: 3 | G14: =IF(ISBLANK(E14),"",E14*10) | H14: =IF(ISBLANK(F14),"",F14*20) | I14: =SUM(G14,H14) -> 0 | J14: =IF(I14>0,12,"") | K14: =IF(M14=E14,"","X") | L14: =IF(N14=F14,"","X") | M14: =(IF(O14="hT",4,0))+(IF(P14="hT",4,0))+(IF(Q14="hT",4,0))+(IF(R14="hT",4,0))+(IF(S14="hT",4,0))+T14+(COUNTIF(W14:AZ14,"hT")) -> 0 | N14: =(IF(O14="x",4,0))+(IF(P14="x",4,0))+(IF(Q14="x",4,0))+(IF(R14="x",4,0))+(IF(S14="x",4,0))+U14+(COUNTIF(W14:AZ14,"x")) -> 0
A15: 4 | G15: =IF(ISBLANK(E15),"",E15*10) | H15: =IF(ISBLANK(F15),"",F15*20) | I15: =SUM(G15,H15) -> 0 | J15: =IF(I15>0,12,"") | K15: =IF(M15=E15,"","X") | L15: =IF(N15=F15,"","X") | M15: =(IF(O15="hT",4,0))+(IF(P15="hT",4,0))+(IF(Q15="hT",4,0))+(IF(R15="hT",4,0))+(IF(S15="hT",4,0))+T15+(COUNTIF(W15:AZ15,"hT")) -> 0 | N15: =(IF(O15="x",4,0))+(IF(P15="x",4,0))+(IF(Q15="x",4,0))+(IF(R15="x",4,0))+(IF(S15="x",4,0))+U15+(COUNTIF(W15:AZ15,"x")) -> 0
A16: 5 | G16: =IF(ISBLANK(E16),"",E16*10) | H16: =IF(ISBLANK(F16),"",F16*20) | I16: =SUM(G16,H16) -> 0 | J16: =IF(I16>0,12,"") | K16: =IF(M16=E16,"","X") | L16: =IF(N16=F16,"","X") | M16: =(IF(O16="hT",4,0))+(IF(P16="hT",4,0))+(IF(Q16="hT",4,0))+(IF(R16="hT",4,0))+(IF(S16="hT",4,0))+T16+(COUNTIF(W16:AZ16,"hT")) -> 0 | N16: =(IF(O16="x",4,0))+(IF(P16="x",4,0))+(IF(Q16="x",4,0))+(IF(R16="x",4,0))+(IF(S16="x",4,0))+U16+(COUNTIF(W16:AZ16,"x")) -> 0
A17: 6 | G17: =IF(ISBLANK(E17),"",E17*10) | H17: =IF(ISBLANK(F17),"",F17*20) | I17: =SUM(G17,H17) -> 0 | J17: =IF(I17>0,12,"") | K17: =IF(M17=E17,"","X") | L17: =IF(N17=F17,"","X") | M17: =(IF(O17="hT",4,0))+(IF(P17="hT",4,0))+(IF(Q17="hT",4,0))+(IF(R17="hT",4,0))+(IF(S17="hT",4,0))+T17+(COUNTIF(W17:AZ17,"hT")) -> 0 | N17: =(IF(O17="x",4,0))+(IF(P17="x",4,0))+(IF(Q17="x",4,0))+(IF(R17="x",4,0))+(IF(S17="x",4,0))+U17+(COUNTIF(W17:AZ17,"x")) -> 0
A18: 7 | G18: =IF(ISBLANK(E18),"",E18*10) | H18: =IF(ISBLANK(F18),"",F18*20) | I18: =SUM(G18,H18) -> 0 | J18: =IF(I18>0,12,"") | K18: =IF(M18=E18,"","X") | L18: =IF(N18=F18,"","X") | M18: =(IF(O18="hT",4,0))+(IF(P18="hT",4,0))+(IF(Q18="hT",4,0))+(IF(R18="hT",4,0))+(IF(S18="hT",4,0))+T18+(COUNTIF(W18:AZ18,"hT")) -> 0 | N18: =(IF(O18="x",4,0))+(IF(P18="x",4,0))+(IF(Q18="x",4,0))+(IF(R18="x",4,0))+(IF(S18="x",4,0))+U18+(COUNTIF(W18:AZ18,"x")) -> 0
A19: 8 | G19: =IF(ISBLANK(E19),"",E19*10) | H19: =IF(ISBLANK(F19),"",F19*20) | I19: =SUM(G19,H19) -> 0 | J19: =IF(I19>0,12,"") | K19: =IF(M19=E19,"","X") | L19: =IF(N19=F19,"","X") | M19: =(IF(O19="hT",4,0))+(IF(P19="hT",4,0))+(IF(Q19="hT",4,0))+(IF(R19="hT",4,0))+(IF(S19="hT",4,0))+T19+(COUNTIF(W19:AZ19,"hT")) -> 0 | N19: =(IF(O19="x",4,0))+(IF(P19="x",4,0))+(IF(Q19="x",4,0))+(IF(R19="x",4,0))+(IF(S19="x",4,0))+U19+(COUNTIF(W19:AZ19,"x")) -> 0
A20: 9 | G20: =IF(ISBLANK(E20),"",E20*10) | H20: =IF(ISBLANK(F20),"",F20*20) | I20: =SUM(G20,H20) -> 0 | J20: =IF(I20>0,12,"") | K20: =IF(M20=E20,"","X") | L20: =IF(N20=F20,"","X") | M20: =(IF(O20="hT",4,0))+(IF(P20="hT",4,0))+(IF(Q20="hT",4,0))+(IF(R20="hT",4,0))+(IF(S20="hT",4,0))+T20+(COUNTIF(W20:AZ20,"hT")) -> 0 | N20: =(IF(O20="x",4,0))+(IF(P20="x",4,0))+(IF(Q20="x",4,0))+(IF(R20="x",4,0))+(IF(S20="x",4,0))+U20+(COUNTIF(W20:AZ20,"x")) -> 0
A21: 10 | G21: =IF(ISBLANK(E21),"",E21*10) | H21: =IF(ISBLANK(F21),"",F21*20) | I21: =SUM(G21,H21) -> 0 | J21: =IF(I21>0,12,"") | K21: =IF(M21=E21,"","X") | L21: =IF(N21=F21,"","X") | M21: =(IF(O21="hT",4,0))+(IF(P21="hT",4,0))+(IF(Q21="hT",4,0))+(IF(R21="hT",4,0))+(IF(S21="hT",4,0))+T21+(COUNTIF(W21:AZ21,"hT")) -> 0 | N21: =(IF(O21="x",4,0))+(IF(P21="x",4,0))+(IF(Q21="x",4,0))+(IF(R21="x",4,0))+(IF(S21="x",4,0))+U21+(COUNTIF(W21:AZ21,"x")) -> 0
A22: 11 | G22: =IF(ISBLANK(E22),"",E22*10) | H22: =IF(ISBLANK(F22),"",F22*20) | I22: =SUM(G22,H22) -> 0 | J22: =IF(I22>0,12,"") | K22: =IF(M22=E22,"","X") | L22: =IF(N22=F22,"","X") | M22: =(IF(O22="hT",4,0))+(IF(P22="hT",4,0))+(IF(Q22="hT",4,0))+(IF(R22="hT",4,0))+(IF(S22="hT",4,0))+T22+(COUNTIF(W22:AZ22,"hT")) -> 0 | N22: =(IF(O22="x",4,0))+(IF(P22="x",4,0))+(IF(Q22="x",4,0))+(IF(R22="x",4,0))+(IF(S22="x",4,0))+U22+(COUNTIF(W22:AZ22,"x")) -> 0
A23: 12 | G23: =IF(ISBLANK(E23),"",E23*10) | H23: =IF(ISBLANK(F23),"",F23*20) | I23: =SUM(G23,H23) -> 0 | J23: =IF(I23>0,12,"") | K23: =IF(M23=E23,"","X") | L23: =IF(N23=F23,"","X") | M23: =(IF(O23="hT",4,0))+(IF(P23="hT",4,0))+(IF(Q23="hT",4,0))+(IF(R23="hT",4,0))+(IF(S23="hT",4,0))+T23+(COUNTIF(W23:AZ23,"hT")) -> 0 | N23: =(IF(O23="x",4,0))+(IF(P23="x",4,0))+(IF(Q23="x",4,0))+(IF(R23="x",4,0))+(IF(S23="x",4,0))+U23+(COUNTIF(W23:AZ23,"x")) -> 0
A24: 13 | G24: =IF(ISBLANK(E24),"",E24*10) | H24: =IF(ISBLANK(F24),"",F24*20) | I24: =SUM(G24,H24) -> 0 | J24: =IF(I24>0,12,"") | K24: =IF(M24=E24,"","X") | L24: =IF(N24=F24,"","X") | M24: =(IF(O24="hT",4,0))+(IF(P24="hT",4,0))+(IF(Q24="hT",4,0))+(IF(R24="hT",4,0))+(IF(S24="hT",4,0))+T24+(COUNTIF(W24:AZ24,"hT")) -> 0 | N24: =(IF(O24="x",4,0))+(IF(P24="x",4,0))+(IF(Q24="x",4,0))+(IF(R24="x",4,0))+(IF(S24="x",4,0))+U24+(COUNTIF(W24:AZ24,"x")) -> 0
... A111: 100 | G111: =IF(ISBLANK(E111),"",E111*10) | H111: =IF(ISBLANK(F111),"",F111*20) | I111: =SUM(G111,H111) -> 0 | J111: =IF(I111>0,12,"") | K111: =IF(M111=E111,"","X") | L111: =IF(N111=F111,"","X") | M111: =(IF(O111="hT",4,0))+(IF(P111="hT",4,0))+(IF(Q111="hT",4,0))+(IF(R111="hT",4,0))+(IF(S111="hT",4,0))+T111+(COUNTIF(W111:AZ111,"hT")) -> 0 | N111: =(IF(O111="x",4,0))+(IF(P111="x",4,0))+(IF(Q111="x",4,0))+(IF(R111="x",4,0))+(IF(S111="x",4,0))+U111+(COUNTIF(W111:AZ111,"x")) -> 0
B112: Anzahl Kinder | C112: =COUNTA(C12:C111) -> 0 | D112: Total | E112: =SUM(E12:E111) -> 0 | F112: =SUM(F12:F111) -> 0 | G112: =SUM(G12:G111) -> 0 | H112: =SUM(H12:H111) -> 0 | I112: =SUM(I12:I111) -> 0 | J112: =IF(SUM(J12:J111)=0,0,IF(SUM(J12:J111)<20,20,SUM(J12:J111))) -> 0
A115: Nr. | B115: Bemerkung

Sheet Mai
A1: Abrechnungsformular kantonale Betreuungsgutschriften (BeGu) im Vorschulbereich | H1: SHR 860.100 und SHR 860.101
A3: Abrechnung kompakt | C3: 46143
A4: BeGu Total 1/2 Tag | C4: =$G$112 -> 0
A5: BeGu Total ganzer Tag | C5: =$H$112 -> 0 | T5: Legende
A6: BeGu Total | C6: =$I$112 -> 0 | T6: x = ganzer Krippentag (resp. kostenpflichtiger Ferien- / Krankheitstag)
A7: Entschädigung | T7: hT = 1/2 Krippentag (resp. kostenpflichtiger Ferien- / Krankheitstag)
A8: Totalbetrag | C8: =C6+C7 -> 0 | T8: f = Ferien / Krankheit (kostenfrei)
A9: Angewiesen am | C9: =Jahresübersicht!E13 -> -
O10: Ausfüllen, wenn pauschal 4 Wochen (plus Zusatztage) verrechnet werden | W10: Ausfüllen, wenn tatsächliche Anzahl Tage im Monat (plus Zusatztage) verrechnet werden (Zusatztage können farbig markiert werden)
A11: Nr. | B11: Name | C11: Vorname | D11: Geburtsdatum | E11: 1/2 Tage (min. 4h) | F11: Tage (min. 8h) | G11: BeGu 1/2 Tag | H11: BeGu ganzer Tag | I11: BeGu Total | J11: Entschädi- gung | K11: Abgleich HT | L11: Abgleich GT | M11: 1/2 Tage | N11: ganze Tage | O11: Montag | P11: Dienstag | Q11: Mittwoch | R11: Donnerstag | S11: Freitag | T11: Anzahl abweichende 1/2 Tage | U11: Anzahl abweichende ganze Tage | W11: 1 | X11: 2 | Y11: 3 | Z11: 4 | AA11: 5 | AB11: 6 | AC11: 7 | AD11: 8 | AE11: 9 | AF11: 10 | AG11: 11 | AH11: 12 | AI11: 13 | AJ11: 14 | AK11: 15 | AL11: 16 | AM11: 17 | AN11: 18 | AO11: 19 | AP11: 20 | AQ11: 21 | AR11: 22 | AS11: 23 | AT11: 24 | AU11: 25 | AV11: 26 | AW11: 27 | AX11: 28 | AY11: 29 | AZ11: 30 | BA11: 31
A12: 1 | G12: =IF(ISBLANK(E12),"",E12*10) | H12: =IF(ISBLANK(F12),"",F12*20) | I12: =SUM(G12,H12) -> 0 | J12: =IF(I12>0,12,"") | K12: =IF(M12=E12,"","X") | L12: =IF(N12=F12,"","X") | M12: =(IF(O12="hT",4,0))+(IF(P12="hT",4,0))+(IF(Q12="hT",4,0))+(IF(R12="hT",4,0))+(IF(S12="hT",4,0))+T12+(COUNTIF(W12:BA12,"hT")) -> 0 | N12: =(IF(O12="x",4,0))+(IF(P12="x",4,0))+(IF(Q12="x",4,0))+(IF(R12="x",4,0))+(IF(S12="x",4,0))+U12+(COUNTIF(W12:BA12,"x")) -> 0 | V12: Entweder ↑ oder ↓ ausfüllen!
A13: 2 | G13: =IF(ISBLANK(E13),"",E13*10) | H13: =IF(ISBLANK(F13),"",F13*20) | I13: =SUM(G13,H13) -> 0 | J13: =IF(I13>0,12,"") | K13: =IF(M13=E13,"","X") | L13: =IF(N13=F13,"","X") | M13: =(IF(O13="hT",4,0))+(IF(P13="hT",4,0))+(IF(Q13="hT",4,0))+(IF(R13="hT",4,0))+(IF(S13="hT",4,0))+T13+(COUNTIF(W13:BA13,"hT")) -> 0 | N13: =(IF(O13="x",4,0))+(IF(P13="x",4,0))+(IF(Q13="x",4,0))+(IF(R13="x",4,0))+(IF(S13="x",4,0))+U13+(COUNTIF(W13:BA13,"x")) -> 0
A14: 3 | G14: =IF(ISBLANK(E14),"",E14*10) | H14: =IF(ISBLANK(F14),"",F14*20) | I14: =SUM(G14,H14) -> 0 | J14: =IF(I14>0,12,"") | K14: =IF(M14=E14,"","X") | L14: =IF(N14=F14,"","X") | M14: =(IF(O14="hT",4,0))+(IF(P14="hT",4,0))+(IF(Q14="hT",4,0))+(IF(R14="hT",4,0))+(IF(S14="hT",4,0))+T14+(COUNTIF(W14:BA14,"hT")) -> 0 | N14: =(IF(O14="x",4,0))+(IF(P14="x",4,0))+(IF(Q14="x",4,0))+(IF(R14="x",4,0))+(IF(S14="x",4,0))+U14+(COUNTIF(W14:BA14,"x")) -> 0
A15: 4 | G15: =IF(ISBLANK(E15),"",E15*10) | H15: =IF(ISBLANK(F15),"",F15*20) | I15: =SUM(G15,H15) -> 0 | J15: =IF(I15>0,12,"") | K15: =IF(M15=E15,"","X") | L15: =IF(N15=F15,"","X") | M15: =(IF(O15="hT",4,0))+(IF(P15="hT",4,0))+(IF(Q15="hT",4,0))+(IF(R15="hT",4,0))+(IF(S15="hT",4,0))+T15+(COUNTIF(W15:BA15,"hT")) -> 0 | N15: =(IF(O15="x",4,0))+(IF(P15="x",4,0))+(IF(Q15="x",4,0))+(IF(R15="x",4,0))+(IF(S15="x",4,0))+U15+(COUNTIF(W15:BA15,"x")) -> 0
A16: 5 | G16: =IF(ISBLANK(E16),"",E16*10) | H16: =IF(ISBLANK(F16),"",F16*20) | I16: =SUM(G16,H16) -> 0 | J16: =IF(I16>0,12,"") | K16: =IF(M16=E16,"","X") | L16: =IF(N16=F16,"","X") | M16: =(IF(O16="hT",4,0))+(IF(P16="hT",4,0))+(IF(Q16="hT",4,0))+(IF(R16="hT",4,0))+(IF(S16="hT",4,0))+T16+(COUNTIF(W16:BA16,"hT")) -> 0 | N16: =(IF(O16="x",4,0))+(IF(P16="x",4,0))+(IF(Q16="x",4,0))+(IF(R16="x",4,0))+(IF(S16="x",4,0))+U16+(COUNTIF(W16:BA16,"x")) -> 0
A17: 6 | G17: =IF(ISBLANK(E17),"",E17*10) | H17: =IF(ISBLANK(F17),"",F17*20) | I17: =SUM(G17,H17) -> 0 | J17: =IF(I17>0,12,"") | K17: =IF(M17=E17,"","X") | L17: =IF(N17=F17,"","X") | M17: =(IF(O17="hT",4,0))+(IF(P17="hT",4,0))+(IF(Q17="hT",4,0))+(IF(R17="hT",4,0))+(IF(S17="hT",4,0))+T17+(COUNTIF(W17:BA17,"hT")) -> 0 | N17: =(IF(O17="x",4,0))+(IF(P17="x",4,0))+(IF(Q17="x",4,0))+(IF(R17="x",4,0))+(IF(S17="x",4,0))+U17+(COUNTIF(W17:BA17,"x")) -> 0
A18: 7 | G18: =IF(ISBLANK(E18),"",E18*10) | H18: =IF(ISBLANK(F18),"",F18*20) | I18: =SUM(G18,H18) -> 0 | J18: =IF(I18>0,12,"") | K18: =IF(M18=E18,"","X") | L18: =IF(N18=F18,"","X") | M18: =(IF(O18="hT",4,0))+(IF(P18="hT",4,0))+(IF(Q18="hT",4,0))+(IF(R18="hT",4,0))+(IF(S18="hT",4,0))+T18+(COUNTIF(W18:BA18,"hT")) -> 0 | N18: =(IF(O18="x",4,0))+(IF(P18="x",4,0))+(IF(Q18="x",4,0))+(IF(R18="x",4,0))+(IF(S18="x",4,0))+U18+(COUNTIF(W18:BA18,"x")) -> 0
A19: 8 | G19: =IF(ISBLANK(E19),"",E19*10) | H19: =IF(ISBLANK(F19),"",F19*20) | I19: =SUM(G19,H19) -> 0 | J19: =IF(I19>0,12,"") | K19: =IF(M19=E19,"","X") | L19: =IF(N19=F19,"","X") | M19: =(IF(O19="hT",4,0))+(IF(P19="hT",4,0))+(IF(Q19="hT",4,0))+(IF(R19="hT",4,0))+(IF(S19="hT",4,0))+T19+(COUNTIF(W19:BA19,"hT")) -> 0 | N19: =(IF(O19="x",4,0))+(IF(P19="x",4,0))+(IF(Q19="x",4,0))+(IF(R19="x",4,0))+(IF(S19="x",4,0))+U19+(COUNTIF(W19:BA19,"x")) -> 0
A20: 9 | G20: =IF(ISBLANK(E20),"",E20*10) | H20: =IF(ISBLANK(F20),"",F20*20) | I20: =SUM(G20,H20) -> 0 | J20: =IF(I20>0,12,"") | K20: =IF(M20=E20,"","X") | L20: =IF(N20=F20,"","X") | M20: =(IF(O20="hT",4,0))+(IF(P20="hT",4,0))+(IF(Q20="hT",4,0))+(IF(R20="hT",4,0))+(IF(S20="hT",4,0))+T20+(COUNTIF(W20:BA20,"hT")) -> 0 | N20: =(IF(O20="x",4,0))+(IF(P20="x",4,0))+(IF(Q20="x",4,0))+(IF(R20="x",4,0))+(IF(S20="x",4,0))+U20+(COUNTIF(W20:BA20,"x")) -> 0
A21: 10 | G21: =IF(ISBLANK(E21),"",E21*10) | H21: =IF(ISBLANK(F21),"",F21*20) | I21: =SUM(G21,H21) -> 0 | J21: =IF(I21>0,12,"") | K21: =IF(M21=E21,"","X") | L21: =IF(N21=F21,"","X") | M21: =(IF(O21="hT",4,0))+(IF(P21="hT",4,0))+(IF(Q21="hT",4,0))+(IF(R21="hT",4,0))+(IF(S21="hT",4,0))+T21+(COUNTIF(W21:BA21,"hT")) -> 0 | N21: =(IF(O21="x",4,0))+(IF(P21="x",4,0))+(IF(Q21="x",4,0))+(IF(R21="x",4,0))+(IF(S21="x",4,0))+U21+(COUNTIF(W21:BA21,"x")) -> 0
A22: 11 | G22: =IF(ISBLANK(E22),"",E22*10) | H22: =IF(ISBLANK(F22),"",F22*20) | I22: =SUM(G22,H22) -> 0 | J22: =IF(I22>0,12,"") | K22: =IF(M22=E22,"","X") | L22: =IF(N22=F22,"","X") | M22: =(IF(O22="hT",4,0))+(IF(P22="hT",4,0))+(IF(Q22="hT",4,0))+(IF(R22="hT",4,0))+(IF(S22="hT",4,0))+T22+(COUNTIF(W22:BA22,"hT")) -> 0 | N22: =(IF(O22="x",4,0))+(IF(P22="x",4,0))+(IF(Q22="x",4,0))+(IF(R22="x",4,0))+(IF(S22="x",4,0))+U22+(COUNTIF(W22:BA22,"x")) -> 0
A23: 12 | G23: =IF(ISBLANK(E23),"",E23*10) | H23: =IF(ISBLANK(F23),"",F23*20) | I23: =SUM(G23,H23) -> 0 | J23: =IF(I23>0,12,"") | K23: =IF(M23=E23,"","X") | L23: =IF(N23=F23,"","X") | M23: =(IF(O23="hT",4,0))+(IF(P23="hT",4,0))+(IF(Q23="hT",4,0))+(IF(R23="hT",4,0))+(IF(S23="hT",4,0))+T23+(COUNTIF(W23:BA23,"hT")) -> 0 | N23: =(IF(O23="x",4,0))+(IF(P23="x",4,0))+(IF(Q23="x",4,0))+(IF(R23="x",4,0))+(IF(S23="x",4,0))+U23+(COUNTIF(W23:BA23,"x")) -> 0
A24: 13 | G24: =IF(ISBLANK(E24),"",E24*10) | H24: =IF(ISBLANK(F24),"",F24*20) | I24: =SUM(G24,H24) -> 0 | J24: =IF(I24>0,12,"") | K24: =IF(M24=E24,"","X") | L24: =IF(N24=F24,"","X") | M24: =(IF(O24="hT",4,0))+(IF(P24="hT",4,0))+(IF(Q24="hT",4,0))+(IF(R24="hT",4,0))+(IF(S24="hT",4,0))+T24+(COUNTIF(W24:BA24,"hT")) -> 0 | N24: =(IF(O24="x",4,0))+(IF(P24="x",4,0))+(IF(Q24="x",4,0))+(IF(R24="x",4,0))+(IF(S24="x",4,0))+U24+(COUNTIF(W24:BA24,"x")) -> 0
... A111: 100 | G111: =IF(ISBLANK(E111),"",E111*10) | H111: =IF(ISBLANK(F111),"",F111*20) | I111: =SUM(G111,H111) -> 0 | J111: =IF(I111>0,12,"") | K111: =IF(M111=E111,"","X") | L111: =IF(N111=F111,"","X") | M111: =(IF(O111="hT",4,0))+(IF(P111="hT",4,0))+(IF(Q111="hT",4,0))+(IF(R111="hT",4,0))+(IF(S111="hT",4,0))+T111+(COUNTIF(W111:BA111,"hT")) -> 0 | N111: =(IF(O111="x",4,0))+(IF(P111="x",4,0))+(IF(Q111="x",4,0))+(IF(R111="x",4,0))+(IF(S111="x",4,0))+U111+(COUNTIF(W111:BA111,"x")) -> 0
B112: Anzahl Kinder | C112: =COUNTA(C12:C111) -> 0 | D112: Total | E112: =SUM(E12:E111) -> 0 | F112: =SUM(F12:F111) -> 0 | G112: =SUM(G12:G111) -> 0 | H112: =SUM(H12:H111) -> 0 | I112: =SUM(I12:I111) -> 0 | J112: =IF(SUM(J12:J111)=0,0,IF(SUM(J12:J111)<20,20,SUM(J12:J111))) -> 0
A115: Nr. | B115: Bemerkung

Sheet Juni
A1: Abrechnungsformular kantonale Betreuungsgutschriften (BeGu) im Vorschulbereich | H1: SHR 860.100 und SHR 860.101
A3: Abrechnung kompakt | C3: 46174
A4: BeGu Total 1/2 Tag | C4: =$G$112 -> 0
A5: BeGu Total ganzer Tag | C5: =$H$112 -> 0 | T5: Legende
A6: BeGu Total | C6: =$I$112 -> 0 | T6: x = ganzer Krippentag (resp. kostenpflichtiger Ferien- / Krankheitstag)
A7: Entschädigung | T7: hT = 1/2 Krippentag (resp. kostenpflichtiger Ferien- / Krankheitstag)
A8: Totalbetrag | C8: =C6+C7 -> 0 | T8: f = Ferien / Krankheit (kostenfrei)
A9: Angewiesen am | C9: =Jahresübersicht!E14 -> -
O10: Ausfüllen, wenn pauschal 4 Wochen (plus Zusatztage) verrechnet werden | W10: Ausfüllen, wenn tatsächliche Anzahl Tage im Monat (plus Zusatztage) verrechnet werden (Zusatztage können farbig markiert werden)
A11: Nr. | B11: Name | C11: Vorname | D11: Geburtsdatum | E11: 1/2 Tage (min. 4h) | F11: Tage (min. 8h) | G11: BeGu 1/2 Tag | H11: BeGu ganzer Tag | I11: BeGu Total | J11: Entschädi- gung | K11: Abgleich HT | L11: Abgleich GT | M11: 1/2 Tage | N11: ganze Tage | O11: Montag | P11: Dienstag | Q11: Mittwoch | R11: Donnerstag | S11: Freitag | T11: Anzahl abweichende 1/2 Tage | U11: Anzahl abweichende ganze Tage | W11: 1 | X11: 2 | Y11: 3 | Z11: 4 | AA11: 5 | AB11: 6 | AC11: 7 | AD11: 8 | AE11: 9 | AF11: 10 | AG11: 11 | AH11: 12 | AI11: 13 | AJ11: 14 | AK11: 15 | AL11: 16 | AM11: 17 | AN11: 18 | AO11: 19 | AP11: 20 | AQ11: 21 | AR11: 22 | AS11: 23 | AT11: 24 | AU11: 25 | AV11: 26 | AW11: 27 | AX11: 28 | AY11: 29 | AZ11: 30
A12: 1 | G12: =IF(ISBLANK(E12),"",E12*10) | H12: =IF(ISBLANK(F12),"",F12*20) | I12: =SUM(G12,H12) -> 0 | J12: =IF(I12>0,12,"") | K12: =IF(M12=E12,"","X") | L12: =IF(N12=F12,"","X") | M12: =(IF(O12="hT",4,0))+(IF(P12="hT",4,0))+(IF(Q12="hT",4,0))+(IF(R12="hT",4,0))+(IF(S12="hT",4,0))+T12+(COUNTIF(W12:AZ12,"hT")) -> 0 | N12: =(IF(O12="x",4,0))+(IF(P12="x",4,0))+(IF(Q12="x",4,0))+(IF(R12="x",4,0))+(IF(S12="x",4,0))+U12+(COUNTIF(W12:AZ12,"x")) -> 0 | V12: Entweder ↑ oder ↓ ausfüllen!
A13: 2 | G13: =IF(ISBLANK(E13),"",E13*10) | H13: =IF(ISBLANK(F13),"",F13*20) | I13: =SUM(G13,H13) -> 0 | J13: =IF(I13>0,12,"") | K13: =IF(M13=E13,"","X") | L13: =IF(N13=F13,"","X") | M13: =(IF(O13="hT",4,0))+(IF(P13="hT",4,0))+(IF(Q13="hT",4,0))+(IF(R13="hT",4,0))+(IF(S13="hT",4,0))+T13+(COUNTIF(W13:AZ13,"hT")) -> 0 | N13: =(IF(O13="x",4,0))+(IF(P13="x",4,0))+(IF(Q13="x",4,0))+(IF(R13="x",4,0))+(IF(S13="x",4,0))+U13+(COUNTIF(W13:AZ13,"x")) -> 0
A14: 3 | G14: =IF(ISBLANK(E14),"",E14*10) | H14: =IF(ISBLANK(F14),"",F14*20) | I14: =SUM(G14,H14) -> 0 | J14: =IF(I14>0,12,"") | K14: =IF(M14=E14,"","X") | L14: =IF(N14=F14,"","X") | M14: =(IF(O14="hT",4,0))+(IF(P14="hT",4,0))+(IF(Q14="hT",4,0))+(IF(R14="hT",4,0))+(IF(S14="hT",4,0))+T14+(COUNTIF(W14:AZ14,"hT")) -> 0 | N14: =(IF(O14="x",4,0))+(IF(P14="x",4,0))+(IF(Q14="x",4,0))+(IF(R14="x",4,0))+(IF(S14="x",4,0))+U14+(COUNTIF(W14:AZ14,"x")) -> 0
A15: 4 | G15: =IF(ISBLANK(E15),"",E15*10) | H15: =IF(ISBLANK(F15),"",F15*20) | I15: =SUM(G15,H15) -> 0 | J15: =IF(I15>0,12,"") | K15: =IF(M15=E15,"","X") | L15: =IF(N15=F15,"","X") | M15: =(IF(O15="hT",4,0))+(IF(P15="hT",4,0))+(IF(Q15="hT",4,0))+(IF(R15="hT",4,0))+(IF(S15="hT",4,0))+T15+(COUNTIF(W15:AZ15,"hT")) -> 0 | N15: =(IF(O15="x",4,0))+(IF(P15="x",4,0))+(IF(Q15="x",4,0))+(IF(R15="x",4,0))+(IF(S15="x",4,0))+U15+(COUNTIF(W15:AZ15,"x")) -> 0
A16: 5 | G16: =IF(ISBLANK(E16),"",E16*10) | H16: =IF(ISBLANK(F16),"",F16*20) | I16: =SUM(G16,H16) -> 0 | J16: =IF(I16>0,12,"") | K16: =IF(M16=E16,"","X") | L16: =IF(N16=F16,"","X") | M16: =(IF(O16="hT",4,0))+(IF(P16="hT",4,0))+(IF(Q16="hT",4,0))+(IF(R16="hT",4,0))+(IF(S16="hT",4,0))+T16+(COUNTIF(W16:AZ16,"hT")) -> 0 | N16: =(IF(O16="x",4,0))+(IF(P16="x",4,0))+(IF(Q16="x",4,0))+(IF(R16="x",4,0))+(IF(S16="x",4,0))+U16+(COUNTIF(W16:AZ16,"x")) -> 0
A17: 6 | G17: =IF(ISBLANK(E17),"",E17*10) | H17: =IF(ISBLANK(F17),"",F17*20) | I17: =SUM(G17,H17) -> 0 | J17: =IF(I17>0,12,"") | K17: =IF(M17=E17,"","X") | L17: =IF(N17=F17,"","X") | M17: =(IF(O17="hT",4,0))+(IF(P17="hT",4,0))+(IF(Q17="hT",4,0))+(IF(R17="hT",4,0))+(IF(S17="hT",4,0))+T17+(COUNTIF(W17:AZ17,"hT")) -> 0 | N17: =(IF(O17="x",4,0))+(IF(P17="x",4,0))+(IF(Q17="x",4,0))+(IF(R17="x",4,0))+(IF(S17="x",4,0))+U17+(COUNTIF(W17:AZ17,"x")) -> 0
A18: 7 | G18: =IF(ISBLANK(E18),"",E18*10) | H18: =IF(ISBLANK(F18),"",F18*20) | I18: =SUM(G18,H18) -> 0 | J18: =IF(I18>0,12,"") | K18: =IF(M18=E18,"","X") | L18: =IF(N18=F18,"","X") | M18: =(IF(O18="hT",4,0))+(IF(P18="hT",4,0))+(IF(Q18="hT",4,0))+(IF(R18="hT",4,0))+(IF(S18="hT",4,0))+T18+(COUNTIF(W18:AZ18,"hT")) -> 0 | N18: =(IF(O18="x",4,0))+(IF(P18="x",4,0))+(IF(Q18="x",4,0))+(IF(R18="x",4,0))+(IF(S18="x",4,0))+U18+(COUNTIF(W18:AZ18,"x")) -> 0
A19: 8 | G19: =IF(ISBLANK(E19),"",E19*10) | H19: =IF(ISBLANK(F19),"",F19*20) | I19: =SUM(G19,H19) -> 0 | J19: =IF(I19>0,12,"") | K19: =IF(M19=E19,"","X") | L19: =IF(N19=F19,"","X") | M19: =(IF(O19="hT",4,0))+(IF(P19="hT",4,0))+(IF(Q19="hT",4,0))+(IF(R19="hT",4,0))+(IF(S19="hT",4,0))+T19+(COUNTIF(W19:AZ19,"hT")) -> 0 | N19: =(IF(O19="x",4,0))+(IF(P19="x",4,0))+(IF(Q19="x",4,0))+(IF(R19="x",4,0))+(IF(S19="x",4,0))+U19+(COUNTIF(W19:AZ19,"x")) -> 0
A20: 9 | G20: =IF(ISBLANK(E20),"",E20*10) | H20: =IF(ISBLANK(F20),"",F20*20) | I20: =SUM(G20,H20) -> 0 | J20: =IF(I20>0,12,"") | K20: =IF(M20=E20,"","X") | L20: =IF(N20=F20,"","X") | M20: =(IF(O20="hT",4,0))+(IF(P20="hT",4,0))+(IF(Q20="hT",4,0))+(IF(R20="hT",4,0))+(IF(S20="hT",4,0))+T20+(COUNTIF(W20:AZ20,"hT")) -> 0 | N20: =(IF(O20="x",4,0))+(IF(P20="x",4,0))+(IF(Q20="x",4,0))+(IF(R20="x",4,0))+(IF(S20="x",4,0))+U20+(COUNTIF(W20:AZ20,"x")) -> 0
A21: 10 | G21: =IF(ISBLANK(E21),"",E21*10) | H21: =IF(ISBLANK(F21),"",F21*20) | I21: =SUM(G21,H21) -> 0 | J21: =IF(I21>0,12,"") | K21: =IF(M21=E21,"","X") | L21: =IF(N21=F21,"","X") | M21: =(IF(O21="hT",4,0))+(IF(P21="hT",4,0))+(IF(Q21="hT",4,0))+(IF(R21="hT",4,0))+(IF(S21="hT",4,0))+T21+(COUNTIF(W21:AZ21,"hT")) -> 0 | N21: =(IF(O21="x",4,0))+(IF(P21="x",4,0))+(IF(Q21="x",4,0))+(IF(R21="x",4,0))+(IF(S21="x",4,0))+U21+(COUNTIF(W21:AZ21,"x")) -> 0
A22: 11 | G22: =IF(ISBLANK(E22),"",E22*10) | H22: =IF(ISBLANK(F22),"",F22*20) | I22: =SUM(G22,H22) -> 0 | J22: =IF(I22>0,12,"") | K22: =IF(M22=E22,"","X") | L22: =IF(N22=F22,"","X") | M22: =(IF(O22="hT",4,0))+(IF(P22="hT",4,0))+(IF(Q22="hT",4,0))+(IF(R22="hT",4,0))+(IF(S22="hT",4,0))+T22+(COUNTIF(W22:AZ22,"hT")) -> 0 | N22: =(IF(O22="x",4,0))+(IF(P22="x",4,0))+(IF(Q22="x",4,0))+(IF(R22="x",4,0))+(IF(S22="x",4,0))+U22+(COUNTIF(W22:AZ22,"x")) -> 0
A23: 12 | G23: =IF(ISBLANK(E23),"",E23*10) | H23: =IF(ISBLANK(F23),"",F23*20) | I23: =SUM(G23,H23) -> 0 | J23: =IF(I23>0,12,"") | K23: =IF(M23=E23,"","X") | L23: =IF(N23=F23,"","X") | M23: =(IF(O23="hT",4,0))+(IF(P23="hT",4,0))+(IF(Q23="hT",4,0))+(IF(R23="hT",4,0))+(IF(S23="hT",4,0))+T23+(COUNTIF(W23:AZ23,"hT")) -> 0 | N23: =(IF(O23="x",4,0))+(IF(P23="x",4,0))+(IF(Q23="x",4,0))+(IF(R23="x",4,0))+(IF(S23="x",4,0))+U23+(COUNTIF(W23:AZ23,"x")) -> 0
A24: 13 | G24: =IF(ISBLANK(E24),"",E24*10) | H24: =IF(ISBLANK(F24),"",F24*20) | I24: =SUM(G24,H24) -> 0 | J24: =IF(I24>0,12,"") | K24: =IF(M24=E24,"","X") | L24: =IF(N24=F24,"","X") | M24: =(IF(O24="hT",4,0))+(IF(P24="hT",4,0))+(IF(Q24="hT",4,0))+(IF(R24="hT",4,0))+(IF(S24="hT",4,0))+T24+(COUNTIF(W24:AZ24,"hT")) -> 0 | N24: =(IF(O24="x",4,0))+(IF(P24="x",4,0))+(IF(Q24="x",4,0))+(IF(R24="x",4,0))+(IF(S24="x",4,0))+U24+(COUNTIF(W24:AZ24,"x")) -> 0
... A111: 100 | G111: =IF(ISBLANK(E111),"",E111*10) | H111: =IF(ISBLANK(F111),"",F111*20) | I111: =SUM(G111,H111) -> 0 | J111: =IF(I111>0,12,"") | K111: =IF(M111=E111,"","X") | L111: =IF(N111=F111,"","X") | M111: =(IF(O111="hT",4,0))+(IF(P111="hT",4,0))+(IF(Q111="hT",4,0))+(IF(R111="hT",4,0))+(IF(S111="hT",4,0))+T111+(COUNTIF(W111:AZ111,"hT")) -> 0 | N111: =(IF(O111="x",4,0))+(IF(P111="x",4,0))+(IF(Q111="x",4,0))+(IF(R111="x",4,0))+(IF(S111="x",4,0))+U111+(COUNTIF(W111:AZ111,"x")) -> 0
B112: Anzahl Kinder | C112: =COUNTA(C12:C111) -> 0 | D112: Total | E112: =SUM(E12:E111) -> 0 | F112: =SUM(F12:F111) -> 0 | G112: =SUM(G12:G111) -> 0 | H112: =SUM(H12:H111) -> 0 | I112: =SUM(I12:I111) -> 0 | J112: =IF(SUM(J12:J111)=0,0,IF(SUM(J12:J111)<20,20,SUM(J12:J111))) -> 0
A115: Nr. | B115: Bemerkung

Sheet Juli
A1: Abrechnungsformular kantonale Betreuungsgutschriften (BeGu) im Vorschulbereich | H1: SHR 860.100 und SHR 860.101
A3: Abrechnung kompakt | C3: 46204
A4: BeGu Total 1/2 Tag | C4: =$G$112 -> 0
A5: BeGu Total ganzer Tag | C5: =$H$112 -> 0 | T5: Legende
A6: BeGu Total | C6: =$I$112 -> 0 | T6: x = ganzer Krippentag (resp. kostenpflichtiger Ferien- / Krankheitstag)
A7: Entschädigung | T7: hT = 1/2 Krippentag (resp. kostenpflichtiger Ferien- / Krankheitstag)
A8: Totalbetrag | C8: =C6+C7 -> 0 | T8: f = Ferien / Krankheit (kostenfrei)
A9: Angewiesen am | C9: =Jahresübersicht!E15 -> -
O10: Ausfüllen, wenn pauschal 4 Wochen (plus Zusatztage) verrechnet werden | W10: Ausfüllen, wenn tatsächliche Anzahl Tage im Monat (plus Zusatztage) verrechnet werden (Zusatztage können farbig markiert werden)
A11: Nr. | B11: Name | C11: Vorname | D11: Geburtsdatum | E11: 1/2 Tage (min. 4h) | F11: Tage (min. 8h) | G11: BeGu 1/2 Tag | H11: BeGu ganzer Tag | I11: BeGu Total | J11: Entschädi- gung | K11: Abgleich HT | L11: Abgleich GT | M11: 1/2 Tage | N11: ganze Tage | O11: Montag | P11: Dienstag | Q11: Mittwoch | R11: Donnerstag | S11: Freitag | T11: Anzahl abweichende 1/2 Tage | U11: Anzahl abweichende ganze Tage | W11: 1 | X11: 2 | Y11: 3 | Z11: 4 | AA11: 5 | AB11: 6 | AC11: 7 | AD11: 8 | AE11: 9 | AF11: 10 | AG11: 11 | AH11: 12 | AI11: 13 | AJ11: 14 | AK11: 15 | AL11: 16 | AM11: 17 | AN11: 18 | AO11: 19 | AP11: 20 | AQ11: 21 | AR11: 22 | AS11: 23 | AT11: 24 | AU11: 25 | AV11: 26 | AW11: 27 | AX11: 28 | AY11: 29 | AZ11: 30 | BA11: 31
A12: 1 | G12: =IF(ISBLANK(E12),"",E12*10) | H12: =IF(ISBLANK(F12),"",F12*20) | I12: =SUM(G12,H12) -> 0 | J12: =IF(I12>0,12,"") | K12: =IF(M12=E12,"","X") | L12: =IF(N12=F12,"","X") | M12: =(IF(O12="hT",4,0))+(IF(P12="hT",4,0))+(IF(Q12="hT",4,0))+(IF(R12="hT",4,0))+(IF(S12="hT",4,0))+T12+(COUNTIF(W12:BA12,"hT")) -> 0 | N12: =(IF(O12="x",4,0))+(IF(P12="x",4,0))+(IF(Q12="x",4,0))+(IF(R12="x",4,0))+(IF(S12="x",4,0))+U12+(COUNTIF(W12:BA12,"x")) -> 0 | V12: Entweder ↑ oder ↓ ausfüllen!
A13: 2 | G13: =IF(ISBLANK(E13),"",E13*10) | H13: =IF(ISBLANK(F13),"",F13*20) | I13: =SUM(G13,H13) -> 0 | J13: =IF(I13>0,12,"") | K13: =IF(M13=E13,"","X") | L13: =IF(N13=F13,"","X") | M13: =(IF(O13="hT",4,0))+(IF(P13="hT",4,0))+(IF(Q13="hT",4,0))+(IF(R13="hT",4,0))+(IF(S13="hT",4,0))+T13+(COUNTIF(W13:BA13,"hT")) -> 0 | N13: =(IF(O13="x",4,0))+(IF(P13="x",4,0))+(IF(Q13="x",4,0))+(IF(R13="x",4,0))+(IF(S13="x",4,0))+U13+(COUNTIF(W13:BA13,"x")) -> 0
A14: 3 | G14: =IF(ISBLANK(E14),"",E14*10) | H14: =IF(ISBLANK(F14),"",F14*20) | I14: =SUM(G14,H14) -> 0 | J14: =IF(I14>0,12,"") | K14: =IF(M14=E14,"","X") | L14: =IF(N14=F14,"","X") | M14: =(IF(O14="hT",4,0))+(IF(P14="hT",4,0))+(IF(Q14="hT",4,0))+(IF(R14="hT",4,0))+(IF(S14="hT",4,0))+T14+(COUNTIF(W14:BA14,"hT")) -> 0 | N14: =(IF(O14="x",4,0))+(IF(P14="x",4,0))+(IF(Q14="x",4,0))+(IF(R14="x",4,0))+(IF(S14="x",4,0))+U14+(COUNTIF(W14:BA14,"x")) -> 0
A15: 4 | G15: =IF(ISBLANK(E15),"",E15*10) | H15: =IF(ISBLANK(F15),"",F15*20) | I15: =SUM(G15,H15) -> 0 | J15: =IF(I15>0,12,"") | K15: =IF(M15=E15,"","X") | L15: =IF(N15=F15,"","X") | M15: =(IF(O15="hT",4,0))+(IF(P15="hT",4,0))+(IF(Q15="hT",4,0))+(IF(R15="hT",4,0))+(IF(S15="hT",4,0))+T15+(COUNTIF(W15:BA15,"hT")) -> 0 | N15: =(IF(O15="x",4,0))+(IF(P15="x",4,0))+(IF(Q15="x",4,0))+(IF(R15="x",4,0))+(IF(S15="x",4,0))+U15+(COUNTIF(W15:BA15,"x")) -> 0
A16: 5 | G16: =IF(ISBLANK(E16),"",E16*10) | H16: =IF(ISBLANK(F16),"",F16*20) | I16: =SUM(G16,H16) -> 0 | J16: =IF(I16>0,12,"") | K16: =IF(M16=E16,"","X") | L16: =IF(N16=F16,"","X") | M16: =(IF(O16="hT",4,0))+(IF(P16="hT",4,0))+(IF(Q16="hT",4,0))+(IF(R16="hT",4,0))+(IF(S16="hT",4,0))+T16+(COUNTIF(W16:BA16,"hT")) -> 0 | N16: =(IF(O16="x",4,0))+(IF(P16="x",4,0))+(IF(Q16="x",4,0))+(IF(R16="x",4,0))+(IF(S16="x",4,0))+U16+(COUNTIF(W16:BA16,"x")) -> 0
A17: 6 | G17: =IF(ISBLANK(E17),"",E17*10) | H17: =IF(ISBLANK(F17),"",F17*20) | I17: =SUM(G17,H17) -> 0 | J17: =IF(I17>0,12,"") | K17: =IF(M17=E17,"","X") | L17: =IF(N17=F17,"","X") | M17: =(IF(O17="hT",4,0))+(IF(P17="hT",4,0))+(IF(Q17="hT",4,0))+(IF(R17="hT",4,0))+(IF(S17="hT",4,0))+T17+(COUNTIF(W17:BA17,"hT")) -> 0 | N17: =(IF(O17="x",4,0))+(IF(P17="x",4,0))+(IF(Q17="x",4,0))+(IF(R17="x",4,0))+(IF(S17="x",4,0))+U17+(COUNTIF(W17:BA17,"x")) -> 0
A18: 7 | G18: =IF(ISBLANK(E18),"",E18*10) | H18: =IF(ISBLANK(F18),"",F18*20) | I18: =SUM(G18,H18) -> 0 | J18: =IF(I18>0,12,"") | K18: =IF(M18=E18,"","X") | L18: =IF(N18=F18,"","X") | M18: =(IF(O18="hT",4,0))+(IF(P18="hT",4,0))+(IF(Q18="hT",4,0))+(IF(R18="hT",4,0))+(IF(S18="hT",4,0))+T18+(COUNTIF(W18:BA18,"hT")) -> 0 | N18: =(IF(O18="x",4,0))+(IF(P18="x",4,0))+(IF(Q18="x",4,0))+(IF(R18="x",4,0))+(IF(S18="x",4,0))+U18+(COUNTIF(W18:BA18,"x")) -> 0
A19: 8 | G19: =IF(ISBLANK(E19),"",E19*10) | H19: =IF(ISBLANK(F19),"",F19*20) | I19: =SUM(G19,H19) -> 0 | J19: =IF(I19>0,12,"") | K19: =IF(M19=E19,"","X") | L19: =IF(N19=F19,"","X") | M19: =(IF(O19="hT",4,0))+(IF(P19="hT",4,0))+(IF(Q19="hT",4,0))+(IF(R19="hT",4,0))+(IF(S19="hT",4,0))+T19+(COUNTIF(W19:BA19,"hT")) -> 0 | N19: =(IF(O19="x",4,0))+(IF(P19="x",4,0))+(IF(Q19="x",4,0))+(IF(R19="x",4,0))+(IF(S19="x",4,0))+U19+(COUNTIF(W19:BA19,"x")) -> 0
A20: 9 | G20: =IF(ISBLANK(E20),"",E20*10) | H20: =IF(ISBLANK(F20),"",F20*20) | I20: =SUM(G20,H20) -> 0 | J20: =IF(I20>0,12,"") | K20: =IF(M20=E20,"","X") | L20: =IF(N20=F20,"","X") | M20: =(IF(O20="hT",4,0))+(IF(P20="hT",4,0))+(IF(Q20="hT",4,0))+(IF(R20="hT",4,0))+(IF(S20="hT",4,0))+T20+(COUNTIF(W20:BA20,"hT")) -> 0 | N20: =(IF(O20="x",4,0))+(IF(P20="x",4,0))+(IF(Q20="x",4,0))+(IF(R20="x",4,0))+(IF(S20="x",4,0))+U20+(COUNTIF(W20:BA20,"x")) -> 0
A21: 10 | G21: =IF(ISBLANK(E21),"",E21*10) | H21: =IF(ISBLANK(F21),"",F21*20) | I21: =SUM(G21,H21) -> 0 | J21: =IF(I21>0,12,"") | K21: =IF(M21=E21,"","X") | L21: =IF(N21=F21,"","X") | M21: =(IF(O21="hT",4,0))+(IF(P21="hT",4,0))+(IF(Q21="hT",4,0))+(IF(R21="hT",4,0))+(IF(S21="hT",4,0))+T21+(COUNTIF(W21:BA21,"hT")) -> 0 | N21: =(IF(O21="x",4,0))+(IF(P21="x",4,0))+(IF(Q21="x",4,0))+(IF(R21="x",4,0))+(IF(S21="x",4,0))+U21+(COUNTIF(W21:BA21,"x")) -> 0
A22: 11 | G22: =IF(ISBLANK(E22),"",E22*10) | H22: =IF(ISBLANK(F22),"",F22*20) | I22: =SUM(G22,H22) -> 0 | J22: =IF(I22>0,12,"") | K22: =IF(M22=E22,"","X") | L22: =IF(N22=F22,"","X") | M22: =(IF(O22="hT",4,0))+(IF(P22="hT",4,0))+(IF(Q22="hT",4,0))+(IF(R22="hT",4,0))+(IF(S22="hT",4,0))+T22+(COUNTIF(W22:BA22,"hT")) -> 0 | N22: =(IF(O22="x",4,0))+(IF(P22="x",4,0))+(IF(Q22="x",4,0))+(IF(R22="x",4,0))+(IF(S22="x",4,0))+U22+(COUNTIF(W22:BA22,"x")) -> 0
A23: 12 | G23: =IF(ISBLANK(E23),"",E23*10) | H23: =IF(ISBLANK(F23),"",F23*20) | I23: =SUM(G23,H23) -> 0 | J23: =IF(I23>0,12,"") | K23: =IF(M23=E23,"","X") | L23: =IF(N23=F23,"","X") | M23: =(IF(O23="hT",4,0))+(IF(P23="hT",4,0))+(IF(Q23="hT",4,0))+(IF(R23="hT",4,0))+(IF(S23="hT",4,0))+T23+(COUNTIF(W23:BA23,"hT")) -> 0 | N23: =(IF(O23="x",4,0))+(IF(P23="x",4,0))+(IF(Q23="x",4,0))+(IF(R23="x",4,0))+(IF(S23="x",4,0))+U23+(COUNTIF(W23:BA23,"x")) -> 0
A24: 13 | G24: =IF(ISBLANK(E24),"",E24*10) | H24: =IF(ISBLANK(F24),"",F24*20) | I24: =SUM(G24,H24) -> 0 | J24: =IF(I24>0,12,"") | K24: =IF(M24=E24,"","X") | L24: =IF(N24=F24,"","X") | M24: =(IF(O24="hT",4,0))+(IF(P24="hT",4,0))+(IF(Q24="hT",4,0))+(IF(R24="hT",4,0))+(IF(S24="hT",4,0))+T24+(COUNTIF(W24:BA24,"hT")) -> 0 | N24: =(IF(O24="x",4,0))+(IF(P24="x",4,0))+(IF(Q24="x",4,0))+(IF(R24="x",4,0))+(IF(S24="x",4,0))+U24+(COUNTIF(W24:BA24,"x")) -> 0
