Workbook
Name akjahr: 'A_ Personal'!$D$3
Name Ein_A: B_Schlüssel!$H$58
Name Ein_B: B_Schlüssel!$H$59
Name Ein_C: B_Schlüssel!$H$60
Name Ein_CA: B_Schlüssel!$H$61
Name SozL: C_Betriebsrechnung!$D$15
Name stellen: 'A_ Personal'!$D$46:$D$56
Name Version: 'A_ Personal'!$E$1
Name ZSR: 'A_ Personal'!$C$6

Sheet A_ Personal
A1: Gesundheitsamt Kanton Schffhausen | E1: Version 2025/2
A3: =D2_eigene_KORE!$A$3 -> Spitex-Kennzahlenset | C3: Jahr | D3: 2025
A4: Formular A: Personen und Stellen analog BFS Spitex-Codes
A6: ZSR-Nummer
A7: BUR-Nummer
A8: Organisation | D8: Name
A9: E-Mail-Adresse
A10: Telefon Nr.
A12: Code BFS Spitex | C12: KORE | D12: Personen | E12: Stellen VZÄ
A13: 100 | B13: Pflegefachfrau FH | C13: 310
A14: 101 | B14: Master of Science Pflege FH | C14: 310
A15: 102 | B15: Master of Science Nursing FH | C15: 310
A16: 103 | B16: PhD Nursing Science | C16: 310
A17: 110 | B17: Dipl. Pflegefachfrau/-mann | C17: 311
A18: 111 | B18: Krankenschwester/-pfleger Diplom II | C18: 311
A19: 112 | B19: Dipl. Krankenschwester-/Pfleger AKP | C19: 311
A20: 113 | B20: Hebamme | C20: 311
A21: 120 | B21: Pflegefachfrau DNI | C21: 312
A22: 121 | B22: Prakt. Krankenpflege (FA SRK) | C22: 312
A23: 130 | B23: Fachfrau Gesundheit (FAGE) | C23: 312
A24: 131 | B24: Med. Praxisassistentin | C24: 312
... A38: 155 | B38: Keine spez. Ausbildung (Angehörigenpfl.) | C38: 319
A39: - | B39: Praktikanten | C39: 318
A41: Total | D41: =SUM(D13:D40) -> 0 | E41: =SUM(E13:E40) -> 0
A43: Zusammenfassung in KORE-Gruppen
A45: KORE Gruppe | B45: Text | C45: =+D12 -> Personen | D45: =+E12 -> Stellen VZÄ
A46: =MID(B46,1,3) -> 310 | B46: 310 Dipl. Pflegefachpersonal mit Zusatzdiplom oder Master | C46: =SUMIF($C$13:C$39,A46,$D$13:$D$39) -> 0 | D46: =SUMIF($C$13:$C$39,$A46,$E$13:$E$39) -> 0
A47: =MID(B47,1,3) -> 311 | B47: 311 Diplomiertes Fachpersonal | C47: =SUMIF($C$13:C$39,A47,$D$13:$D$39) -> 0 | D47: =SUMIF($C$13:$C$39,$A47,$E$13:$E$39) -> 0
A48: =MID(B48,1,3) -> 312 | B48: 312 Personal mit beruflicher Grundbildung (Pf/Be) | C48: =SUMIF($C$13:C$39,A48,$D$13:$D$39) -> 0 | D48: =SUMIF($C$13:$C$39,$A48,$E$13:$E$39) -> 0
A49: =MID(B49,1,3) -> 313 | B49: 313 Assistenz | C49: =SUMIF($C$13:C$39,A49,$D$13:$D$39) -> 0 | D49: =SUMIF($C$13:$C$39,$A49,$E$13:$E$39) -> 0
A50: =MID(B50,1,3) -> 314 | B50: 314 Grundkurs Pflegehelferin SRK | C50: =SUMIF($C$13:C$39,A50,$D$13:$D$39) -> 0 | D50: =SUMIF($C$13:$C$39,$A50,$E$13:$E$39) -> 0
A51: 414 | B51: 314 Grundkurs Pflegehelferin SRK (Angehörige) | C51: =SUMIF($C$13:C$39,A51,$D$13:$D$39) -> 0 | D51: =SUMIF($C$13:$C$39,$A51,$E$13:$E$39) -> 0
A52: =MID(B52,1,3) -> 315 | B52: 315 Ohne spezifische Ausbildung | C52: =SUMIF($C$13:C$39,A52,$D$13:$D$39) -> 0 | D52: =SUMIF($C$13:$C$39,$A52,$E$13:$E$39) -> 0
A53: 415 | B53: 415 Ohne spezifische Ausbildung (Angehörige) | C53: =SUMIF($C$13:C$39,A53,$D$13:$D$39) -> 0 | D53: =SUMIF($C$13:$C$39,$A53,$E$13:$E$39) -> 0
A54: =MID(B54,1,3) -> 316 | B54: 316 Auszubildene Pflege HF, FH | C54: =SUMIF($C$13:C$39,A54,$D$13:$D$39) -> 0 | D54: =SUMIF($C$13:$C$39,$A54,$E$13:$E$39) -> 0
A55: =MID(B55,1,3) -> 317 | B55: 317 Auszubildende Pflege FaGe, FaBe, AGS | C55: =SUMIF($C$13:C$39,A55,$D$13:$D$39) -> 0 | D55: =SUMIF($C$13:$C$39,$A55,$E$13:$E$39) -> 0
A56: =MID(B56,1,3) -> 318 | B56: 318 Praktikanten | C56: =SUMIF($C$13:C$39,A56,$D$13:$D$39) -> 0 | D56: =SUMIF($C$13:$C$39,$A56,$E$13:$E$39) -> 0
A57: =MID(B57,1,3) -> 319 | B57: 319 Pflegende Angehörige | C57: =SUMIF($C$13:C$39,A57,$D$13:$D$39) -> 0 | D57: =SUMIF($C$13:$C$39,$A57,$E$13:$E$39) -> 0
A59: Total | C59: =SUM(C46:C58) -> 0 | D59: =SUM(D46:D58) -> 0
A61: Bemerkungen zuhanden Gesundheitsamt

Sheet Hilfsblatt Stunden
A3: Aufteilung verrechnete Stunden gemäss BFS-Spitex
B5: 0 bis 4 Jahre | C5: 5 bis 19 Jahre | D5: 20 bis 64 Jahre | E5: 65 bis 79 Jahre | F5: über 80 Jahre | G5: Total
A6: Abklärung und Beratung | D6: 19 | E6: 113 | F6: 309 | G6: =SUM(B6:F6) -> 441
A7: Untersuchung & Behandlung | D7: 282 | E7: 1635 | F7: 5290 | G7: =SUM(B7:F7) -> 7207
A8: Grundpflege | D8: 17 | E8: 1636 | F8: 9696 | G8: =SUM(B8:F8) -> 11349
A9: Akut & Uebergang | D9: 0
A10: Total KLV | B10: =SUM(B6:B9) -> 0 | C10: =SUM(C6:C9) -> 0 | D10: =SUM(D6:D9) -> 318 | E10: =SUM(E6:E9) -> 3384 | F10: =SUM(F6:F9) -> 15295 | G10: =SUM(B10:F10) -> 18997
A11: Hauswirtschaft | D11: 547 | E11: 2857 | F11: 13756 | G11: =SUM(B11:F11) -> 17160
A12: Gesamttotal | B12: =+B10+B11 -> 0 | C12: =+C10+C11 -> 0 | D12: =+D10+D11 -> 865 | E12: =+E10+E11 -> 6241 | F12: =+F10+F11 -> 29051 | G12: =SUM(B12:F12) -> 36157

Sheet B_Schlüssel
A1: Gesundheitsamt Kanton Schffhausen | J1: =+Version -> Version 2025/2
A3: =D2_eigene_KORE!$A$3 -> Spitex-Kennzahlenset
A5: Formular B: Errechnung Umlageschlüssel
A7: Organisation | C7: ='A_ Personal'!C8 | F7: ="ZSR "&ZSR -> ZSR
A8: Rechnungsjahr | C8: =akjahr -> 2025
A9: 1. Stundenleistungen und Pesonalkosten im Kanton Schaffhausen
A10: (Spitex Finanzmanual, Kontenrahmen Pos. 310-329)
A11: Basis: Personalkosten je Qualifikation
A12: Datenherkunft: Zeit/Leistungserfassung & Lohnsystem
A13: 1.1 Aufteilung auf Kostenstellen gemäss Spitex-Manual-Kontenplan (ohne übrlge Dienstleistungen)
A14: Qualifikation | C14: Pensen (VZÄ) | D14: Verrechnete Stunden | E14: Personalkos-ten ohne Soz.Vers. | F14: Kosten je Std. | G14: Prozent im Vgl. zum Ø
A16: 310 Dipl. Pflegefachpersonal mit Zusatzdiplom / Master | B16: 1 | C16: ='A_ Personal'!D46 -> 0 | F16: =IFERROR(E16/D16,0) -> 0 | G16: =IFERROR(ROUND(F16/$F$27,3),0) -> 0
A17: 311 Diplomiertes Pflegefachpersonal | B17: 1 | C17: ='A_ Personal'!D47 -> 0 | F17: =IFERROR(E17/D17,0) -> 0 | G17: =IFERROR(ROUND(F17/$F$27,3),0) -> 0
A18: 312 Personal mit berufl. Grundbildung (FABE, FAGE) | B18: 2 | C18: ='A_ Personal'!D48 -> 0 | F18: =IFERROR(E18/D18,0) -> 0 | G18: =IFERROR(ROUND(F18/$F$27,3),0) -> 0
A19: 313 Assistenz (in Pflege) | B19: 3 | C19: ='A_ Personal'!D49 -> 0 | F19: =IFERROR(E19/D19,0) -> 0 | G19: =IFERROR(ROUND(F19/$F$27,3),0) -> 0
A20: 314 Grundkurs Pflegehelferin SRK | B20: 3 | C20: ='A_ Personal'!D50 -> 0 | F20: =IFERROR(E20/D20,0) -> 0 | G20: =IFERROR(ROUND(F20/$F$27,3),0) -> 0
A21: 315 Ohne spezifische Ausbildung | B21: 4 | C21: ='A_ Personal'!D52 -> 0 | F21: =IFERROR(E21/D21,0) -> 0 | G21: =IFERROR(ROUND(F21/$F$27,3),0) -> 0
A22: 316 Auszubildene Pflege HF, FH | B22: 5 | C22: ='A_ Personal'!D54 -> 0 | F22: =IFERROR(E22/D22,0) -> 0 | G22: =IFERROR(ROUND(F22/$F$27,3),0) -> 0
A23: 317 Auszubildende Pflege FaGe, FaBe, AGS | B23: 5 | C23: ='A_ Personal'!D55 -> 0 | F23: =IFERROR(E23/D23,0) -> 0 | G23: =IFERROR(ROUND(F23/$F$27,3),0) -> 0
A24: 318 Praktikanten | B24: 4 | C24: ='A_ Personal'!D56 -> 0 | F24: =IFERROR(E24/D24,0) -> 0 | G24: =IFERROR(ROUND(F24/$F$27,3),0) -> 0
A25: 319 Pflegende Angehörige | B25: 7 | C25: ='A_ Personal'!D57 -> 0 | G25: =IFERROR(ROUND(F25/$F$27,3),0) -> 0
A26: 320-329 Besoldung weitere Fachbereiche | B26: 6 | F26: =IFERROR(E26/D26,0) -> 0 | G26: =IFERROR(ROUND(F26/$F$27,3),0) -> 0
A27: Total KLV Pensen und Stunden | C27: =SUM(C16:C26) -> 0 | D27: =SUM(D15:D26) -> 0 | E27: =SUM(E15:E26) -> 0 | F27: =IFERROR(ROUND(E27/D27,2),0) -> 0 | H27: =+IF(E27=Basis!B14+Basis!B18+Basis!C18,"","Differenz zu Angabe in Formular C") | J27: =IF(E27=Basis!B14+Basis!B18+Basis!C18,"",B_Schlüssel!E27-Basis!B14)
A28: 330-339 Leitung und Verwaltung | E28: =C_Betriebsrechnung!D14 -> 0 | F28: =IFERROR(E28/D28,0) -> 0
A29: Total rapportierte Pensen und Stunden | C29: =+C27+C28 -> 0 | D29: =+D27+D28 -> 0 | E29: =+E27+E28 -> 0 | F29: =IFERROR(ROUND(E29/D29,2),0) -> 0
A31: 1.2. Stundenverteilung auf Kostenträger (KLV- und AÜP-Leistungen A bis C und weitere) nach Qualifikation (nur Std. im Kanton SH)
C32: Total Std | E32: Stundenverteilung auf Kostenträger
E33: Std. KLV-A | F33: Std. KLV-B | G33: Std. KLV-C normal | H33: Std. KLV-C Angehörige | I33: Std. Hauswirt-schaft & Betreuung | J33: Std. übrige Dienst-Leistungen
A34: HF, FH | C34: =SUMIF(B_Schlüssel!$B$16:$B$26,1,B_Schlüssel!D$16:D$26) -> 0 | K34: =+IF(C34=SUM(E34:J34),"","Bitte Differenz bereinigen") | L34: =IF(C34-SUM(E6:J34)=0,"",C34-SUM(E34:J34))
A35: FABE/FAGE | C35: =SUMIF(B_Schlüssel!$B$16:$B$26,2,B_Schlüssel!D$16:D$26) -> 0 | K35: =+IF(C35=SUM(E35:J35),"","Bitte Differenz bereinigen") | L35: =IF(C35-SUM(E7:J35)=0,"",C35-SUM(E35:J35))
A36: Assistenz | C36: =SUMIF(B_Schlüssel!$B$16:$B$26,3,B_Schlüssel!D$16:D$26) -> 0 | K36: =+IF(C36=SUM(E36:J36),"","Bitte Differenz bereinigen") | L36: =IF(C36-SUM(E4:J36)=0,"",C36-SUM(E36:J36))
A37: Pflegende Angehörige | C37: =SUMIF(B_Schlüssel!$B$16:$B$26,7,B_Schlüssel!D$16:D$26) -> 0 | K37: =+IF(C37=SUM(E37:J37),"","Bitte Differenz bereinigen") | L37: =IF(C37-SUM(E9:J37)=0,"",C37-SUM(E37:J37))
A38: ohne spezifische Ausbildung | C38: =SUMIF(B_Schlüssel!$B$16:$B$26,4,B_Schlüssel!D$16:D$26) -> 0 | K38: =+IF(C38=SUM(E38:J38),"","Bitte Differenz bereinigen") | L38: =IF(C38-SUM(E9:J38)=0,"",C38-SUM(E38:J38))
A39: in Ausbildung | C39: =SUMIF(B_Schlüssel!$B$16:$B$26,5,B_Schlüssel!D$16:D$26) -> 0 | K39: =+IF(C39=SUM(E39:J39),"","Bitte Differenz bereinigen") | L39: =IF(C39-SUM(E10:J39)=0,"",C39-SUM(E39:J39))
A40: Weitere Fachbereiche | C40: =SUMIF(B_Schlüssel!$B$16:$B$26,6,B_Schlüssel!D$16:D$26) -> 0 | K40: =+IF(C40=SUM(E40:J40),"","Bitte Differenz bereinigen") | L40: =IF(C40-SUM(E11:J40)=0,"",C40-SUM(E40:J40))
A41: Total verrechnete KLV Stunden | C41: =SUM(C34:C40) -> 0 | E41: =SUM(E34:E40) -> 0 | F41: =SUM(F34:F40) -> 0 | G41: =SUM(G34:G40) -> 0 | H41: =SUM(H34:H40) -> 0 | I41: =SUM(I34:I40) -> 0 | J41: =SUM(J34:J40) -> 0
A42: Schlüssel Verteilung Beiträge öff. Hand | C42: =SUM(E42:J42) -> 0 | E42: =IFERROR(ROUND(E41/$C41,4),0) -> 0 | F42: =IFERROR(ROUND(F41/$C41,4),0) -> 0 | G42: =IFERROR(ROUND(G41/$C41,4),0) -> 0 | H42: =IFERROR(ROUND(H41/$C41,4),0) -> 0 | I42: =IFERROR(ROUND(I41/$C41,4),0) -> 0 | J42: =IFERROR(ROUND(J41/$C41,4),0) -> 0
A43: Schlüssel Verteilung Nebenerträge Spitex | C43: =SUM(E43:J43) -> 0 | E43: =IFERROR(ROUND(E41/SUM($E$41:$I$41),4),0) -> 0 | F43: =IFERROR(ROUND(F41/SUM($E$41:$I$41),4),0) -> 0 | G43: =IFERROR(ROUND(G41/SUM($E$41:$I$41),4),0) -> 0 | H43: =IFERROR(ROUND(H41/SUM($E$41:$I$41),4),0) -> 0 | I43: =IFERROR(ROUND(I41/SUM($E$41:$I$41),4),0) -> 0
A44: 1.3. Personalkostenverteilung auf Kostenträger (KLV- und AÜP-Leistungen A bis C und weitere) nach Qualifikation
A45: HF, FH | C45: =SUMIF(B_Schlüssel!$B$16:$B$26,1,B_Schlüssel!D$16:D$26) -> 0 | D45: =SUMIF(B_Schlüssel!$B$16:$B$26,1,B_Schlüssel!E$16:E$26) -> 0 | E45: =IFERROR(ROUND($D45*E34/$C34,0),0) -> 0 | F45: =IFERROR(ROUND($D45*F34/$C34,0),0) -> 0 | G45: =IFERROR(ROUND($D45*G34/$C34,0),0) -> 0 | H45: =IFERROR(ROUND($D45*H34/$C34,0),0) -> 0 | I45: =IFERROR(ROUND($D45*I34/$C34,0),0) -> 0 | J45: =IFERROR(ROUND($D45*J34/$C34,0),0) -> 0 | K45: =D45-SUM(E45:J45) -> 0
...

Sheet C_Betriebsrechnung
A1: Gesundheitsamt Kanton Schffhausen
A3: Spitex-Kennzahlenset | G3: =B_Schlüssel!J1 -> Version 2025/2
A4: Formular C: Komprimierte Betriebsrechnung
A6: Organisation | C6: ='A_ Personal'!C8 | E6: ="ZSR "&ZSR -> ZSR
A7: Rechnungsjahr | C7: =akjahr -> 2025
A9: Kostenzuordnung zu den Kostenarten siehe Spitex-Finanzmanual | C9: TotaL CHF | D9: davon KLV-Kern DL | E9: davon übrige DL | F9: Total | G9: Prozent
C10: gesamte Unternehmung | D10: im Kanton Schaffhausen | E10: =+D10 -> im Kanton Schaffhausen | F10: =E10 -> im Kanton Schaffhausen | H10: Aufteilung Sozialversicherungsaufwand
A11: 30 | B11: Personalaufwand | C11: =SUM(C12:C17) -> 0 | D11: =SUM(D12:D17) -> 0 | E11: =SUM(E12:E17) -> 0 | F11: =SUM(D11:E11) -> 0 | G11: =IFERROR(F11/F$34,"") | H11: Prozente Verteilung Soz V A | J11: Franken
A12: 310 | B12: Besoldung Pflege, Betreuung, Hauswirtschaft | F12: =SUM(D12:E12) -> 0 | G12: =IFERROR(F12/F$34,"") | H12: =IFERROR(ROUND(D12/SUM($F$12:$F$14),4),0) -> 0 | J12: =ROUND($D$15*H12,0) -> 0
A13: 320 | B13: Besoldung andere Fachbereiche | F13: =SUM(D13:E13) -> 0 | G13: =IFERROR(F13/F$34,"") | H13: =IFERROR(ROUND(D13/SUM($F$12:$F$14),4),0) -> 0 | I13: =IFERROR(ROUND(E13/SUM(F12:F14),4),0) -> 0 | J13: =ROUND($D$15*H13,0) -> 0 | K13: =ROUND($D$15*I13,0) -> 0
A14: 330 | B14: Besoldung Verwaltung, Organisation, Leitung | F14: =SUM(D14:E14) -> 0 | G14: =IFERROR(F14/F$34,"") | H14: =1-SUM(H12:I13) -> 1 | J14: =ROUND($D$15*H14,0) -> 0
A15: 370 | B15: Sozialversicherungsaufwand Total | F15: =SUM(D15:E15) -> 0 | G15: =IFERROR(F15/F$34,"")
A16: 380 | B16: Arbeitsleistungen Dritter | F16: =SUM(D16:E16) -> 0 | G16: =IFERROR(F16/F$34,"") | I16: Spitex DL: | J16: =J12+J13 -> 0
A17: 390 | B17: Sonstiger Personalaufwand | F17: =SUM(D17:E17) -> 0 | G17: =IFERROR(F17/F$34,"")
A18: 40 | B18: Aufwand Material und Dienstleistungen | C18: =SUM(C19:C20) -> 0 | D18: =SUM(D19:D20) -> 0 | E18: =SUM(E19:E20) -> 0 | F18: =SUM(D18:E18) -> 0 | G18: =IFERROR(F18/F$34,"")
A19: 400 | B19: Medizinischer Bedarf | F19: =SUM(D19:E19) -> 0 | G19: =IFERROR(F19/F$34,"")
A20: 460 | B20: Bezogene Dienstleistungen | F20: =SUM(D20:E20) -> 0 | G20: =IFERROR(F20/F$34,"")
B21: davon konzerninterne Verrechnungen | F21: =SUM(D21:E21) -> 0 | G21: =IFERROR(F21/F$34,"")
B22: davon Marketing & Kommunikation | F22: =SUM(D22:E22) -> 0 | G22: =IFERROR(F22/F$34,"")
A23: 50 | B23: Übriger betrieblicher Aufwand | C23: =SUM(C24:C28,C30:C32) -> 0 | D23: =SUM(D24:D28,D30:D32) -> 0 | E23: =SUM(E24:E28,E30:E32) -> 0 | F23: =SUM(D23:E23) -> 0 | G23: =IFERROR(F23/F$34,"")
A24: 520 | B24: Fahrzeug- & Transportaufwand | F24: =SUM(D24:E24) -> 0 | G24: =IFERROR(F24/F$34,"")
A25: 530 | B25: Unterhalt/Reparatur mobile Anlagen (ohne Fz) | F25: =SUM(D25:E25) -> 0 | G25: =IFERROR(F25/F$34,"")
A26: 550 | B26: Raumaufwand | F26: =SUM(D26:E26) -> 0 | G26: =IFERROR(F26/F$34,"")
A27: 560 | B27: Energie und Entsorgung | F27: =SUM(D27:E27) -> 0 | G27: =IFERROR(F27/F$34,"")
A28: 570 | B28: Verwaltung und Informatik | F28: =SUM(D28:E28) -> 0 | G28: =IFERROR(F28/F$34,"")
B29: davon konzerninterne Verrechnungen | F29: =SUM(D29:E29) -> 0 | G29: =IFERROR(F29/F$34,"")
A30: 580 | B30: Sachversicherungen, Abgaben, Gebühren | F30: =SUM(D30:E30) -> 0 | G30: =IFERROR(F30/F$34,"")
A31: 590 | B31: Sonstiger betrieblicher Aufwand, Steuern | F31: =SUM(D31:E31) -> 0 | G31: =IFERROR(F31/F$34,"")
A32: 540 | B32: Abschreibungen und Wertberichtigungen | F32: =SUM(D32:E32) -> 0 | G32: =IFERROR(F32/F$34,"")
A34: Total Aufwand | C34: =+C11+C23+C18 -> 0 | D34: =+D11+D23+D18 -> 0 | E34: =+E11+E23+E18 -> 0 | F34: =SUM(D34:E34) -> 0 | G34: =IFERROR(+G11+G18+G23,"")
A36: 60 | B36: Nettoerlöse aus Lieferungen & Leistungen | C36: =SUM(C38:C43) -> 0 | D36: =SUM(D38:D43) -> 0 | E36: =SUM(E38:E43) -> 0 | F36: =SUM(D36:E36) -> 0 | G36: =IFERROR(F36/F$52,"")
A37: 600 | B37: Nettoerlöse aus KLV-Leistungen | G37: =IFERROR(F37/F$52,"")
B38: von Klienten | F38: =SUM(D38:E38) -> 0 | G38: =IFERROR(F38/F$52,"")
B39: von Versicherern | F39: =SUM(D39:E39) -> 0 | G39: =IFERROR(F39/F$52,"")
B40: von öff. Hand (Restkosten) | F40: =SUM(D40:E40) -> 0 | G40: =IFERROR(F40/F$52,"")
A41: 620 | B41: Nettoerlöse aus Hauswirtschaft und Betreuung | F41: =SUM(D41:E41) -> 0 | G41: =IFERROR(F41/F$52,"")
A42: 630 | B42: Mitgliederbeiträge, Spenden, Legate | F42: =SUM(D42:E42) -> 0 | G42: =IFERROR(F42/F$52,"")
A43: 670 | B43: Andere Erträge | F43: =SUM(D43:E43) -> 0 | G43: =IFERROR(F43/F$52,"")
A45: 65 | B45: Beiträge der öffentlichen Hand und Anderen (ohne Beiträge nach KLV Art. 7) | C45: =SUM(C46:C47) -> 0 | D45: =SUM(D46:D47) -> 0 | E45: =SUM(E46:E47) -> 0 | F45: =SUM(D45:E45) -> 0 | G45: =IFERROR(F45/F$52,"")
B46: Defizitdeckung | F46: =SUM(D46:E46) -> 0 | G46: =IFERROR(F46/F$52,"")
...

Sheet Basis
A1: Gesundheitsamt Kanton Schffhausen | C1: ausgeblendet
A3: Spitex-Kennzahlenset
C4: =Version -> Version 2025/2
A5: Organisation | C5: ='A_ Personal'!D8 -> Name
A6: Rechnungsjahr | C6: =akjahr -> 2025
A8: Umlagebasis
A10: KLV Pflegeleistungen Kanton Schaffhausen
A12: Kosten | B12: KERN DL | C12: ÜBRIGE DL
A13: Personalaufwand Kern-DL | B13: =SUM(B14:B16) -> 0 | C13: =SUM(C14:C16) -> 0
A14: Löhne | B14: =C_Betriebsrechnung!D12 -> 0
A15: Sozialleistungen | B15: =IFERROR(ROUND(C_Betriebsrechnung!D15*C_Betriebsrechnung!H12,0),0) -> 0
A16: Sonstiger Personalaufwand | B16: =C_Betriebsrechnung!D17+C_Betriebsrechnung!D16 -> 0 | C16: =C_Betriebsrechnung!E16+C_Betriebsrechnung!E17 -> 0
A17: Personalaufwand übrige DL | B17: =SUM(B18:B19) -> 0 | C17: =SUM(C18:C19) -> 0
A18: Löhne | B18: =C_Betriebsrechnung!D13 -> 0 | C18: =C_Betriebsrechnung!E13 -> 0
A19: Sozialleistungen | B19: =IFERROR(ROUND(SozL*C_Betriebsrechnung!H13,0),0) -> 0 | C19: =IFERROR(ROUND(SozL*C_Betriebsrechnung!I13,0),0) -> 0
A20: Personalaufwand Verwaltung | B20: =SUM(B21:B22) -> 0 | C20: =SUM(C21:C22) -> 0
A21: Besoldung Verwaltung, Organisation, Leitung | B21: =C_Betriebsrechnung!D14 -> 0 | C21: =C_Betriebsrechnung!K14 -> 0
A22: Sozialleistungen | B22: =IFERROR(ROUND(C_Betriebsrechnung!H14*SozL,0),0) -> 0 | C22: =ROUND(C_Betriebsrechnung!E15*C_Betriebsrechnung!I14,4) -> 0
A23: Sachaufwand | B23: =SUM(B24:B26) -> 0 | C23: =SUM(C24:C26) -> 0
A24: Material + Dienstleistungen Kern-DL | B24: =C_Betriebsrechnung!D18 -> 0
A25: Material + Dienstleistungen übrige DL | C25: =C_Betriebsrechnung!E18 -> 0
A26: Übriger Aufwand | B26: =C_Betriebsrechnung!D23 -> 0 | C26: =C_Betriebsrechnung!E23 -> 0
A28: Total Aufwand | B28: =+B13+B23+B20+B17 -> 0 | C28: =+C13+C23+C20+C17 -> 0
A30: Erträge | B30: CHF | C30: Anteile
A31: Spitex-Dienstleistungen | B31: =+B32 -> 0 | C31: =+C32+C36 -> 0
A32: Erträge KLV und AÜP | B32: =SUM(B33:B35) -> 0 | C32: =SUM(C33:C35) -> 0
A33: davon Klienten | B33: =C_Betriebsrechnung!F38 -> 0 | C33: =C_Betriebsrechnung!H38 -> 0
A34: davon Versicherer | B34: =C_Betriebsrechnung!F39 -> 0 | C34: =C_Betriebsrechnung!H39 -> 0
A35: davon öff. Hand (nur Restkosten) | B35: =C_Betriebsrechnung!F40 -> 0 | C35: =C_Betriebsrechnung!H40 -> 0
A36: Übrige Erträge aus Spitex | B36: =SUM(B37:B38) -> 0 | C36: =SUM(C37:C38) -> 0
A37: Hauswirtschaft | B37: =C_Betriebsrechnung!F41 -> 0 | C37: =C_Betriebsrechnung!H41 -> 0
A38: Weitere Spitex-Einnahmen | B38: =C_Betriebsrechnung!C42 -> 0
A39: Übrige Einnahmen | C39: =C_Betriebsrechnung!F43+C_Betriebsrechnung!F48 -> 0
A40: Beiträge öffentliche Hand (Defizitdeckung) | B40: =C_Betriebsrechnung!F45 -> 0 | C40: =C_Betriebsrechnung!H45 -> 0
A41: Total Ertrag | B41: =SUM(B31,B36,B39,B40) -> 0 | C41: =SUM(C31,C36,C39,C40) -> 0
A43: Erfolg | B43: =B41-B28 -> 0 | C43: =C41-C28 -> 0
C44: plus = Gewinn, minus = Verlust

Sheet D1_KORE
A1: Gesundheitsamt Kanton Schffhausen
A3: Spitex-Kennzahlenset | H3: =Version -> Version 2025/2
A5: Formular D1: Vereinfachte Kostenträgerrechnung
A7: Organisation | C7: ='A_ Personal'!C8 | G7: ="ZSR "&ZSR -> ZSR
A8: Rechnungsjahr | C8: =akjahr -> 2025
A10: Diese Kostenrechnung wird auf der Basis der von Ihnen erfassten Daten automatisch generiert. Sie ist vereinfacht und ersetzt die eigene Kostenrechnung nicht (die teils ab Rechnungsjahr 2027 Pflicht ist).
A13: Einnahmen | B13: Alle Kostenträger | C13: KLV-A Abklärung (500) | D13: KLV-B Unter-suchung (501) | E13: KLV-C Grund-pflege (502, ohne Angehörige) | F13: KLV-C Angehörigen-pflege (502 Grundpflege) | G13: Hauswirtschaft und Betreuung (560) | H13: Übrige DL (andere Fachbereiche, 600 ff.)
A14: Erträge KLV | B14: =SUM(C14:G14) -> 0 | C14: =SUM(C15:C17) -> 0 | D14: =SUM(D15:D17) -> 0 | E14: =SUM(E15:E17) -> 0 | F14: =SUM(F15:F17) -> 0 | I14: =IF(B14-SUM(C14:H14)=0,"",B14-SUM(C14:H14))
A15: Klienten Ist | B15: =Basis!B33 -> 0 | C15: =ROUND($B15*Ein_A,0) -> 0 | D15: =ROUND($B15*Ein_B,0) -> 0 | E15: =B15-SUM(C15:D15,F15) -> 0 | F15: =ROUND($B15*Ein_CA,0) -> 0 | I15: =IF(B15-SUM(C15:H15)=0,"",B15-SUM(C15:H15))
A16: Versicherer | B16: =Basis!B34 -> 0 | C16: =ROUND($B16*Ein_A,0) -> 0 | D16: =ROUND($B16*Ein_B,0) -> 0 | E16: =B16-SUM(C16:D16,F16) -> 0 | F16: =ROUND($B16*Ein_CA,0) -> 0 | I16: =IF(B16-SUM(C16:H16)=0,"",B16-SUM(C16:H16))
A17: öff. Hand | B17: =Basis!B35 -> 0 | C17: =ROUND($B17*Ein_A,0) -> 0 | D17: =ROUND($B17*Ein_B,0) -> 0 | E17: =B17-SUM(C17:D17,F17) -> 0 | F17: =ROUND($B17*Ein_CA,0) -> 0 | I17: =IF(B17-SUM(C17:H17)=0,"",B17-SUM(C17:H17))
C18: =ROUND($B18*Ein_A,0) -> 0 | D18: =ROUND($B18*Ein_B,0) -> 0 | E18: =ROUND($B18*Ein_C,0) -> 0 | F18: =ROUND($B18*Ein_CA,0) -> 0 | I18: =IF(B18-SUM(C18:H18)=0,"",B18-SUM(C18:H18))
A19: Übrige Erträge Spitex | B19: =SUM(B20:B21) -> 0 | C19: =SUM(C20:C21) -> 0 | D19: =SUM(D20:D21) -> 0 | E19: =SUM(E20:E21) -> 0 | F19: =SUM(F20:F21) -> 0 | G19: =SUM(G20:G21) -> 0 | I19: =IF(B19-SUM(C19:H19)=0,"",B19-SUM(C19:H19))
A20: Hauswirtschaft | B20: =Basis!B37 -> 0 | G20: =B20 -> 0 | I20: =IF(B20-SUM(C20:H20)=0,"",B20-SUM(C20:H20))
A21: Weitere Spitex-Einnahmen | B21: =Basis!B38 -> 0 | C21: =ROUND($B21*B_Schlüssel!E43,4) -> 0 | D21: =ROUND($B21*B_Schlüssel!F43,4) -> 0 | E21: =ROUND($B21*B_Schlüssel!G43,4) -> 0 | F21: =ROUND($B21*B_Schlüssel!H43,4) -> 0 | G21: =ROUND($B21*B_Schlüssel!I43,4) -> 0 | I21: =IF(B21-SUM(C21:H21)=0,"",B21-SUM(C21:H21))
I22: =IF(B22-SUM(C22:H22)=0,"",B22-SUM(C22:H22))
A23: Übrige Einnahmen | B23: =Basis!C39 -> 0 | H23: =B23 -> 0 | I23: =IF(B23-SUM(C23:H23)=0,"",B23-SUM(C23:H23))
I24: =IF(B24-SUM(C24:H24)=0,"",B24-SUM(C24:H24))
A25: Beiträge öff. Hand | B25: =Basis!B40 -> 0 | C25: =ROUND($B25*B_Schlüssel!E42,0) -> 0 | D25: =ROUND($B25*B_Schlüssel!F42,0) -> 0 | E25: =ROUND($B25*B_Schlüssel!G42,0) -> 0 | F25: =ROUND($B25*B_Schlüssel!H42,0) -> 0 | G25: =B25-SUM(C25:F25) -> 0 | I25: =IF(B25-SUM(C25:H25)=0,"",B25-SUM(C25:H25))
A26: Total Einnahmen | B26: =SUM(B14,B19,B23,B25) -> 0 | C26: =+C14+C19+C23+C25 -> 0 | D26: =+D14+D19+D23+D25 -> 0 | E26: =+E14+E19+E23+E25 -> 0 | F26: =+F14+F19+F23+F25 -> 0 | G26: =+G14+G19+G23+G25 -> 0 | H26: =+H14+H19+H23+H25 -> 0 | I26: =IF(B26-SUM(C26:H26)=0,"",B26-SUM(C26:H26))
A28: Ausgaben | B28: =B13 -> Alle Kostenträger | C28: =C13 -> KLV-A Abklärung (500) | D28: =D13 -> KLV-B Unter-suchung (501) | E28: =E13 -> KLV-C Grund-pflege (502, ohne Angehörige) | F28: =F13 -> KLV-C Angehörigen-pflege (502 Grundpflege) | G28: =G13 -> Hauswirtschaft und Betreuung (560) | H28: =H13 -> Übrige DL (andere Fachbereiche, 600 ff.)
A29: Personalaufwand | B29: =SUM(B30:B32) -> 0 | C29: =SUM(C30:C32) -> 0 | D29: =SUM(D30:D32) -> 0 | E29: =SUM(E30:E32) -> 0 | F29: =SUM(F30:F32) -> 0 | G29: =SUM(G30:G32) -> 0 | H29: =SUM(H30:H32) -> 0 | I29: =IF(B29-SUM(C29:H29)=0,"",B29-SUM(C29:H29))
A30: =Basis!A14 -> Löhne | B30: =Basis!B14+Basis!C18+Basis!B18 -> 0 | C30: =B_Schlüssel!E52 -> 0 | D30: =B_Schlüssel!F52 -> 0 | E30: =B_Schlüssel!G52 -> 0 | F30: =B_Schlüssel!H52 -> 0 | G30: =B_Schlüssel!I52 -> 0 | H30: =B_Schlüssel!J52 -> 0 | I30: =IF(B30-SUM(C30:H30)=0,"",B30-SUM(C30:H30))
A31: =Basis!A15 -> Sozialleistungen | B31: =Basis!B15+Basis!B19+Basis!C19 -> 0 | C31: =ROUND(C_Betriebsrechnung!$J$16*B_Schlüssel!E54,0) -> 0 | D31: =ROUND(C_Betriebsrechnung!$J$16*B_Schlüssel!F54,0) -> 0 | E31: =ROUND(C_Betriebsrechnung!$J$16*B_Schlüssel!G54,0) -> 0 | F31: =ROUND(C_Betriebsrechnung!$J$16*B_Schlüssel!H54,0) -> 0 | G31: =ROUND(C_Betriebsrechnung!$J$16*B_Schlüssel!I54,0) -> 0 | H31: =B31-SUM(C31:G31) -> 0 | I31: =IF(B31-SUM(C31:H31)=0,"",B31-SUM(C31:H31))
A32: =Basis!A16 -> Sonstiger Personalaufwand | B32: =Basis!B16 -> 0 | C32: =ROUND($B32*B_Schlüssel!E53,0) -> 0 | D32: =ROUND($B32*B_Schlüssel!F53,0) -> 0 | E32: =ROUND($B32*B_Schlüssel!G53,0) -> 0 | F32: =ROUND($B32*B_Schlüssel!H53,0) -> 0 | G32: =ROUND($B32*B_Schlüssel!I53,0) -> 0 | H32: =B32-SUM(C32:G32) -> 0 | I32: =IF(B32-SUM(C32:H32)=0,"",B32-SUM(C32:H32))
I33: =IF(B33-SUM(C33:H33)=0,"",B33-SUM(C33:H33))
A34: Material und Dienstleistungen | B34: =Basis!B24+Basis!C25 -> 0 | C34: =ROUND(Basis!$B24*B_Schlüssel!E42,0) -> 0 | D34: =ROUND(Basis!$B24*B_Schlüssel!F42,0) -> 0 | E34: =ROUND(Basis!$B24*B_Schlüssel!G42,0) -> 0 | F34: =ROUND(Basis!$B24*B_Schlüssel!H42,0) -> 0 | G34: =ROUND(Basis!$B24*B_Schlüssel!I42,0) -> 0 | H34: =B34-SUM(C34:G34) -> 0 | I34: =IF(B34-SUM(C34:H34)=0,"",B34-SUM(C34:H34))
I35: =IF(B35-SUM(C35:H35)=0,"",B35-SUM(C35:H35))
A36: Übriger Aufwand | B36: =Basis!B26+Basis!C26 -> 0 | C36: =ROUND(Basis!$B26*B_Schlüssel!E42,0) -> 0 | D36: =ROUND(Basis!$B26*B_Schlüssel!F42,0) -> 0 | E36: =ROUND(Basis!$B26*B_Schlüssel!G42,0) -> 0 | F36: =ROUND(Basis!$B26*B_Schlüssel!H42,0) -> 0 | G36: =ROUND(Basis!$B26*B_Schlüssel!I42,0) -> 0 | H36: =B36-SUM(C36:G36) -> 0 | I36: =IF(B36-SUM(C36:H36)=0,"",B36-SUM(C36:H36))
A37: Zwischentotal | B37: =+B29+B34+B36 -> 0 | C37: =+C29+C34+C36 -> 0 | D37: =+D29+D34+D36 -> 0 | E37: =+E29+E34+E36 -> 0 | F37: =+F29+F34+F36 -> 0 | G37: =+G29+G34+G36 -> 0 | H37: =+H29+H34+H36 -> 0 | I37: =IF(B37-SUM(C37:H37)=0,"",B37-SUM(C37:H37))
B38: =IFERROR(B37/$B37,0) -> 0 | C38: =IFERROR(C37/$B37,0) -> 0 | D38: =IFERROR(D37/$B37,0) -> 0 | E38: =IFERROR(E37/$B37,0) -> 0 | F38: =IFERROR(F37/$B37,0) -> 0 | G38: =IFERROR(G37/$B37,0) -> 0 | H38: =IFERROR(H37/$B37,0) -> 0 | I38: =IF(B38-SUM(C38:H38)=1,"",B38-SUM(C38:H38)) -> 0
I39: =IF(B39-SUM(C39:H39)=0,"",B39-SUM(C39:H39))
A40: Personalkosten Leitung & Verwaltung | B40: =Basis!B20 -> 0 | C40: =ROUND($B40*C38,0) -> 0 | D40: =ROUND($B40*D38,0) -> 0 | E40: =ROUND($B40*E38,0) -> 0 | F40: =ROUND($B40*F38,0) -> 0 | G40: =ROUND($B40*G38,0) -> 0 | H40: =B40-SUM(C40:G40) -> 0 | I40: =IF(B40-SUM(C40:H40)=0,"",B40-SUM(C40:H40))
I41: =IF(B41-SUM(C41:H41)=0,"",B41-SUM(C41:H41))
A42: Total Ausgaben (Vollkosten) | B42: =SUM(B29+B40+B34+B36) -> 0 | C42: =SUM(C29+C40+C34+C36) -> 0 | D42: =SUM(D29+D40+D34+D36) -> 0 | E42: =SUM(E29+E40+E34+E36) -> 0 | F42: =SUM(F29+F40+F34+F36) -> 0 | G42: =SUM(G29+G40+G34+G36) -> 0 | H42: =SUM(H29+H40+H34+H36) -> 0 | I42: =IF(B42-SUM(C42:H42)=0,"",B42-SUM(C42:H42))
I43: =IF(B43-SUM(C43:H43)=0,"",B43-SUM(C43:H43))
A44: Resultat Kostenträgerrechnung | B44: =B26-B42 -> 0 | C44: =C26-C42 -> 0 | D44: =D26-D42 -> 0 | E44: =E26-E42 -> 0 | F44: =F26-F42 -> 0 | G44: =G26-G42 -> 0 | H44: =H26-H42 -> 0 | I44: =IF(B44-SUM(C44:H44)<>1,"",B44-SUM(C44:H44))
I45: =IF(B45-SUM(C45:H45)=0,"",B45-SUM(C45:H45))
A46: Deckungsgrad | B46: =IFERROR(ROUND(B26/B42,4),0) -> 0 | C46: =IFERROR(ROUND(C26/C42,4),0) -> 0 | D46: =IFERROR(ROUND(D26/D42,4),0) -> 0 | E46: =IFERROR(ROUND(E26/E42,4),0) -> 0 | F46: =IFERROR(ROUND(F26/F42,4),0) -> 0 | G46: =IFERROR(ROUND(G26/G42,4),0) -> 0 | H46: =IFERROR(ROUND(H26/H42,4),0) -> 0
A49: Finanz-Kennzahlen | B49: Alle Kostenträger | C49: Alle KLV-Leistungen (A-C) | D49: =C28 -> KLV-A Abklärung (500) | E49: =D28 -> KLV-B Unter-suchung (501) | F49: =E28 -> KLV-C Grund-pflege (502, ohne Angehörige) | G49: =F28 -> KLV-C Angehörigen-pflege (502 Grundpflege) | H49: Hauswirtschaft und Betreuung (560)
...

Sheet D2_eigene_KORE
A1: Gesundheitsamt Kanton Schffhausen | F1: =Version -> Version 2025/2
A3: Spitex-Kennzahlenset | D3: Dieses Formular ist nur von Spitexbetrieben mit eigener Kostenrechnung auszufüllen. Es wird davon ausgegangen, dass die KORE die nachstehenden Kennzahlen liefert. Formular D1 wird vom GA in diesem Fall nur ergänzend beigezogen.
A5: Formular D2: Für Spitex-Betriebe mit eigener Kostenrechnung
A7: Organisation | C7: ='A_ Personal'!C8 | D7: ="ZSR "&ZSR -> ZSR
A8: Rechnungsjahr | C8: =akjahr -> 2025
A11: 1. KLV Pflegeleistungen Kanton Schaffhausen
B13: Total KLV | C13: KLV-A Abklärung (500) | D13: KLV-B Untersuchung (501) | E13: KLV-C Grundpflege (502, o/Angehörige) | F13: KLV-C Angehörigengrundpflege (502 Grundpflege)
A14: Vollkosten | B14: =SUM(C14:F14) -> 0
A15: Erträge | B15: =SUM(C15:F15) -> 0 | C15: =SUM(C16:C18) -> 0 | D15: =SUM(D16:D18) -> 0 | E15: =SUM(E16:E18) -> 0 | F15: =SUM(F16:F18) -> 0
A16: Klienten Ist | B16: =SUM(C16:F16) -> 0
A17: Versicherer | B17: =SUM(C17:F17) -> 0
A18: öff. Hand | B18: =SUM(C18:F18) -> 0
A19: Ergebnis Kostenträgerrechnung | B19: =SUM(C19:F19) -> 0 | C19: =+C15-C14 -> 0 | D19: =+D15-D14 -> 0 | E19: =+E15-E14 -> 0 | F19: =+F15-F14 -> 0
A20: Total Stunden | B20: =SUM(C20:F20) -> 0
A21: Vollkosten pro Stunde | B21: =IFERROR(ROUND(B14/B20,2),0) -> 0 | C21: =IFERROR(ROUND(C14/C20,2),0) -> 0 | D21: =IFERROR(ROUND(D14/D20,2),0) -> 0 | E21: =IFERROR(ROUND(E14/E20,2),0) -> 0 | F21: =IFERROR(ROUND(F14/F20,2),0) -> 0
A22: Erträge pro Stunde | B22: =IFERROR(ROUND(B15/B20,2),0) -> 0 | C22: =IFERROR(ROUND(C15/C20,2),0) -> 0 | D22: =IFERROR(ROUND(D15/D20,2),0) -> 0 | E22: =IFERROR(ROUND(E15/E20,2),0) -> 0 | F22: =IFERROR(ROUND(F15/F20,2),0) -> 0
A23: Erfolg pro Stunde | B23: =B22-B21 -> 0 | C23: =C22-C21 -> 0 | D23: =D22-D21 -> 0 | E23: =E22-E21 -> 0 | F23: =F22-F21 -> 0
A24: in Prozent Vollkosten | B24: =IFERROR(B23/B21,0) -> 0 | C24: =IFERROR(C23/C21,0) -> 0 | D24: =IFERROR(D23/D21,0) -> 0 | E24: =IFERROR(E23/E21,0) -> 0 | F24: =IFERROR(F23/F21,0) -> 0
A25: Total Anzahl Klienten KLV
A27: 2. Übrige Pflegeleistungen Kanton Schaffhausen (AÜP, IV, MV, UV)
B29: Total KLV | C29: KLV-A Abklärung (500) | D29: KLV-B Untersuchung (501) | E29: KLV-C Grundpflege (502, o/Angehörige) | F29: KLV-C Grundpflege Angehörige (502)
A30: Vollkosten | B30: =SUM(C30:F30) -> 0
A31: Erträge | B31: =SUM(C31:F31) -> 0 | C31: =SUM(C32:C34) -> 0 | D31: =SUM(D32:D34) -> 0 | E31: =SUM(E32:E34) -> 0 | F31: =SUM(F32:F34) -> 0
A32: Klienten Ist | B32: =SUM(C32:F32) -> 0
A33: Versicherer | B33: =SUM(C33:F33) -> 0
A34: öff. Hand | B34: =SUM(C34:F34) -> 0
A35: Ergebnis Kostenträgerrechnung | B35: =SUM(C35:F35) -> 0 | C35: =+C31-C30 -> 0 | D35: =+D31-D30 -> 0 | E35: =+E31-E30 -> 0 | F35: =+F31-F30 -> 0
A36: Total Stunden | B36: =SUM(C36:F36) -> 0
A37: Vollkosten pro Stunde | B37: =IFERROR(ROUND(B30/B36,2),0) -> 0 | C37: =IFERROR(ROUND(C30/C36,2),0) -> 0 | D37: =IFERROR(ROUND(D30/D36,2),0) -> 0 | E37: =IFERROR(ROUND(E30/E36,2),0) -> 0 | F37: =IFERROR(ROUND(F30/F36,2),0) -> 0
A38: Erträge pro Stunde | B38: =IFERROR(ROUND(B31/B36,2),0) -> 0 | C38: =IFERROR(ROUND(C31/C36,2),0) -> 0 | D38: =IFERROR(ROUND(D31/D36,2),0) -> 0 | E38: =IFERROR(ROUND(E31/E36,2),0) -> 0 | F38: =IFERROR(ROUND(F31/F36,2),0) -> 0
A39: Erfolg pro Stunde | B39: =B38-B37 -> 0 | C39: =C38-C37 -> 0 | D39: =D38-D37 -> 0 | E39: =E38-E37 -> 0 | F39: =F38-F37 -> 0
A40: in Prozent Vollkosten | B40: =IFERROR(B39/B37,0) -> 0 | C40: =IFERROR(C39/C37,0) -> 0 | D40: =IFERROR(D39/D37,0) -> 0 | E40: =IFERROR(E39/E37,0) -> 0 | F40: =IFERROR(F39/F37,0) -> 0
A41: Total Anzahl übrige Klienten Pflege
A43: 3. Übrige Leistungen
B45: Total | C45: Hauswirtschaft und Betreuung (560) | D45: Übrige Dienstleistungen (600)
A46: Vollkosten | B46: =SUM(C46:D46) -> 0
A47: Erträge | B47: =SUM(C47:D47) -> 0 | C47: =SUM(C48:C50) -> 0 | D47: =SUM(D48:D50) -> 0
A48: Klienten Ist | B48: =SUM(C48:D48) -> 0
A49: Versicherer | B49: =SUM(C49:D49) -> 0
A50: öff. Hand | B50: =SUM(C50:D50) -> 0
...

Sheet E_Minuten_Gde
A1: Gesundheitsamt Kanton Schffhausen | M1: =Version -> Version 2025/2
A3: =D2_eigene_KORE!$A$3 -> Spitex-Kennzahlenset
A5: Formular E: Verrechnete Minuten pro Gemeinde
A7: Organisation | C7: ='A_ Personal'!C8 | F7: ="ZSR "&ZSR -> ZSR
A8: Rechnungsjahr | C8: =akjahr -> 2025
C10: Anzahl Minuten p.a. absolut | I10: Anzahl Minuten p.a. in %
A11: Lau-fende Nr. | B11: Abrechnung an Gemeinden | C11: KLV-A Abklärung (500) | D11: KLV-B Untersuchung (501) | E11: KLV-C Grund-pflege (502 ohne pflegende Angeh.) | F11: KLV-C Grund-pflege (502 pfl. Angeh.) | G11: Summe | I11: KLV-A Abklärung (500) | J11: KLV-B Untersuchung (501) | K11: KLV-C Grund-pflege (502 ohne pflegende Angeh.) | L11: KLV-C Grund-pflege (502 pfl. Angeh.) | M11: Kontroll-Summe
A12: 1 | B12: Bargen | G12: =+SUM(C12:F12) -> 0 | I12: =IF(C12="","",C12/$G12) | J12: =IF(D12="","",D12/$G12) | K12: =IF(E12="","",E12/$G12) | L12: =IF(F12="","",F12/$G12) | M12: =+SUM(I12:L12) -> 0
A13: =+A12+1 -> 2 | B13: Beggingen | G13: =+SUM(C13:F13) -> 0 | I13: =IF(C13="","",C13/$G13) | J13: =IF(D13="","",D13/$G13) | K13: =IF(E13="","",E13/$G13) | L13: =IF(F13="","",F13/$G13) | M13: =+SUM(I13:L13) -> 0
A14: =+A13+1 -> 3 | B14: Beringen | G14: =+SUM(C14:F14) -> 0 | I14: =IF(C14="","",C14/$G14) | J14: =IF(D14="","",D14/$G14) | K14: =IF(E14="","",E14/$G14) | L14: =IF(F14="","",F14/$G14) | M14: =+SUM(I14:L14) -> 0
A15: =+A14+1 -> 4 | B15: Buch | G15: =+SUM(C15:F15) -> 0 | I15: =IF(C15="","",C15/$G15) | J15: =IF(D15="","",D15/$G15) | K15: =IF(E15="","",E15/$G15) | L15: =IF(F15="","",F15/$G15) | M15: =+SUM(I15:L15) -> 0
A16: =+A15+1 -> 5 | B16: Buchberg | G16: =+SUM(C16:F16) -> 0 | I16: =IF(C16="","",C16/$G16) | J16: =IF(D16="","",D16/$G16) | K16: =IF(E16="","",E16/$G16) | L16: =IF(F16="","",F16/$G16) | M16: =+SUM(I16:L16) -> 0
A17: =+A16+1 -> 6 | B17: Büttenhardt | G17: =+SUM(C17:F17) -> 0 | I17: =IF(C17="","",C17/$G17) | J17: =IF(D17="","",D17/$G17) | K17: =IF(E17="","",E17/$G17) | L17: =IF(F17="","",F17/$G17) | M17: =+SUM(I17:L17) -> 0
A18: =+A17+1 -> 7 | B18: Dörflingen | G18: =+SUM(C18:F18) -> 0 | I18: =IF(C18="","",C18/$G18) | J18: =IF(D18="","",D18/$G18) | K18: =IF(E18="","",E18/$G18) | L18: =IF(F18="","",F18/$G18) | M18: =+SUM(I18:L18) -> 0
A19: =+A18+1 -> 8 | B19: Gächlingen | G19: =+SUM(C19:F19) -> 0 | I19: =IF(C19="","",C19/$G19) | J19: =IF(D19="","",D19/$G19) | K19: =IF(E19="","",E19/$G19) | L19: =IF(F19="","",F19/$G19) | M19: =+SUM(I19:L19) -> 0
A20: =+A19+1 -> 9 | B20: Hallau | G20: =+SUM(C20:F20) -> 0 | I20: =IF(C20="","",C20/$G20) | J20: =IF(D20="","",D20/$G20) | K20: =IF(E20="","",E20/$G20) | L20: =IF(F20="","",F20/$G20) | M20: =+SUM(I20:L20) -> 0
A21: =+A20+1 -> 10 | B21: Hemishofen | G21: =+SUM(C21:F21) -> 0 | I21: =IF(C21="","",C21/$G21) | J21: =IF(D21="","",D21/$G21) | K21: =IF(E21="","",E21/$G21) | L21: =IF(F21="","",F21/$G21) | M21: =+SUM(I21:L21) -> 0
A22: =+A21+1 -> 11 | B22: Löhningen | G22: =+SUM(C22:F22) -> 0 | I22: =IF(C22="","",C22/$G22) | J22: =IF(D22="","",D22/$G22) | K22: =IF(E22="","",E22/$G22) | L22: =IF(F22="","",F22/$G22) | M22: =+SUM(I22:L22) -> 0
A23: =+A22+1 -> 12 | B23: Lohn | G23: =+SUM(C23:F23) -> 0 | I23: =IF(C23="","",C23/$G23) | J23: =IF(D23="","",D23/$G23) | K23: =IF(E23="","",E23/$G23) | L23: =IF(F23="","",F23/$G23) | M23: =+SUM(I23:L23) -> 0
A24: =+A23+1 -> 13 | B24: Merishausen | G24: =+SUM(C24:F24) -> 0 | I24: =IF(C24="","",C24/$G24) | J24: =IF(D24="","",D24/$G24) | K24: =IF(E24="","",E24/$G24) | L24: =IF(F24="","",F24/$G24) | M24: =+SUM(I24:L24) -> 0
... A38: =+A37+1 -> 27 | B38: Gemeinden ausserkantonal | G38: =+SUM(C38:F38) -> 0 | I38: =IF(C38="","",C38/$G38) | J38: =IF(D38="","",D38/$G38) | K38: =IF(E38="","",E38/$G38) | L38: =IF(F38="","",F38/$G38) | M38: =+SUM(I38:L38) -> 0
B39: Summe | C39: =+SUM(C12:C38) -> 0 | D39: =+SUM(D12:D38) -> 0 | E39: =+SUM(E12:E38) -> 0 | F39: =+SUM(F12:F38) -> 0 | G39: =+SUM(G12:G38) -> 0 | I39: =IF(C39=0,"",C39/$G39) | J39: =IF(D39=0,"",D39/$G39) | K39: =IF(E39=0,"",E39/$G39) | L39: =IF(F39=0,"",F39/$G39) | M39: =+SUM(I39:L39) -> 0
A41: Hinweis: Die Summe der mtl. Angaben von Spitex an die Gemeinden (s. Vordruck) muss den Angaben in diesem Blatt entsprechen.
A44: Bemerkungen zuhanden Gesundheitsamt

Sheet KST KOA
A1: Gesundheitsamt Kanton Schffhausen | D1: V4
A3: =D2_eigene_KORE!$A$3 -> Spitex-Kennzahlenset
A5: Formular D: Kosten je Kostenstelle und -art
A6: Organisation | B6: =D2_eigene_KORE!C7
A7: Rechnungsjahr | B7: =D2_eigene_KORE!C8 -> 2025
B9: Kostenstellen Im Minimum braucht es zwei KST: Administration und Pflegeteam, sofern weitere DL angeboten werden sind KST zu ergänzen
B11: Adm. | C11: Pflegeteam A | D11: Pflegeteam B | E11: Pflegeteam C | F11: HWL & Betreuung | G11: UV HWL & Betreuung | H11: Mahlzeitendienste | I11: Fahrdienst | J11: Mütter-/ Väterberatung | K11: Spezialisierte Pflegeleistungen | L11: etc.
C12: 100-102 | F12: 160 | G12: 165 | H12: 200 | I12: 201 | J12: 202 | K12: 261 | L12: ????
A13: KOA-Gruppen:
A14: Löhne Administration
A15: Löhne Pflegepersonal
A16: Sozialabgaben
A17: Weiterbildungskosten
A18: Miete
A19: IT/ Softwarelizenzen
A20: Fahrzeugkosten
A21: Med. Verbrauchsmaterial
A22: Food & Beverage
A23: Sachkosten
A24: Büro- und Administrationsmaterial
... A29: KOA sind auf der KST zulässig
